Workbook

Sheet README
A1: 바이오시밀러 비교 에이전트 정답셋 v0.2 (2026-10-02)
A4: 이번 버전에서 한 일
A5: 1단계 studies | B5: EPAR 3개를 직접 읽고 시험 11개를 정리. 평가 대상 = PK 유사성 시험 4개(SB17-1001, ABP 20190230, CT-P43 1.1 Part 2, CT-P43 1.2) + CT-P43 통합 분석
A6: 2단계 라벨링(A) | B6: Claude가 라벨러 A로 4개 시험 × 32칸 = 128칸 + 추가 분석 19칸을 원문에서 직접 채움. 이미지 표는 페이지를 렌더링해 눈으로 확인
A7: 3단계 규칙 수정 | B7: 라벨링 중 판단이 갈린 13가지를 ambiguity_log 탭에 기록하고 스키마에 반영(analysis_id, 비교 방향, N/n 분리, modality, ADA 정의 등)
A8: 4단계 | B8: 수정된 규칙으로 ABP 654·CT-P43까지 라벨링 완료. B 라벨러용 블라인드 시트는 별도 파일
A10: 아직 정답이 아닌 이유
A11: AI_DRAFT | B11: 모든 칸은 AI 라벨(A)이다. 같은 계열 모델로 에이전트를 만들 경우 같은 실수를 공유할 수 있으므로, 사람 B의 독립 라벨과 일치하거나 조정된 칸만 HUMAN으로 승격해 정답으로 쓴다
A12: B 작업 | B12: B_blind_labeling_v0.2.xlsx를 A 값을 보지 않고 채운 뒤, B_status·B_value_num·B_ci_low·B_ci_high·B_pdf_page를 이 파일 gold_values에 붙여넣으면 agree 열과 summary의 B 일치율이 자동 계산된다
A13: 우선 확인 | B13: PENDING 1칸(CT-P43 1.1 EU/US 결론), IMAGE 근거 34칸(자동 대조 불가)
A15: 탭
A16: summary | B16: 충족률·자동 대조·일치율
A17: gold_values | B17: 정답 본체. 1행 = 1칸. CORE = 평가 격자, EXTRA = 추가 분석·정의(함정 테스트용), EXAMPLE = 형식 예시
A18: studies | B18: 제품별 시험 목록과 평가 대상 지정
A19: field_dictionary | B19: 필드 정의·라벨링 규칙 (v0.2 변경 열 포함)
A20: ambiguity_log | B20: 파일럿에서 발견한 모호성과 규칙 변경 근거
A21: open_questions / synthetic_tests | B21: 열린 질문·함정 테스트 (이번 EPAR 사례로 갱신)
A22: products / sources | B22: 제품 매핑(AUTO)과 원문 해시
A23: enums | B23: 허용 코드
A25: 키 구조
A26: 정답 키 | B26: (study_key, field_id, analysis_id, arm 또는 comparison, analysis_set, timepoint). analysis_id가 없으면 같은 칸에 정답이 여러 개 생긴다(A1)
A28: 범례
A29: 노란 칸 | B29: B가 입력할 칸
A30: 회색 칸 | B30: 자동 수식
A31: 주황 칸 | B31: 사람 판정이 필요한 PENDING 행
A32: 연녹색 키 | B32: EXTRA 행
A33: 파란 기울임 행 | B33: 형식 예시
A35: 채점 규칙 (초안)
A36: 숫자 | B36: 키 일치 + |차이| ≤ 0.01 (원문 자릿수 기준). 신뢰구간 동일
A37: 상태 | B37: status 정확 일치. 정답이 NOT_FOUND인데 숫자를 내면 할루시네이션으로 별도 집계
A38: 출처 | B38: 같은 source_id + pdf_page(또는 alt_locations) ±1. TEXT 근거는 인용 페이지에 값 문자열이 있는지 코드로 확인

Sheet summary
A1: 정답셋 v0.2 현황 (in_eval=Y · CORE 행)
A3: 전체 현황
A4: 지표 | B4: 값 | C4: 설명
A5: 평가 대상 칸 수 | B5: =COUNTIFS(gold_values!$AO$3:$AO$800,"Y",gold_values!$L$3:$L$800,"CORE") -> 128 | C5: CORE 격자 (4개 시험 × 32칸)
A6: REPORTED | B6: =COUNTIFS(gold_values!$AO$3:$AO$800,"Y",gold_values!$L$3:$L$800,"CORE",gold_values!$M$3:$M$800,"REPORTED") -> 108 | C6: 공개 문서에 값이 있음
A7: REDACTED | B7: =COUNTIFS(gold_values!$AO$3:$AO$800,"Y",gold_values!$L$3:$L$800,"CORE",gold_values!$M$3:$M$800,"REDACTED") -> 0 | C7: 가림 처리
A8: NOT_FOUND | B8: =COUNTIFS(gold_values!$AO$3:$AO$800,"Y",gold_values!$L$3:$L$800,"CORE",gold_values!$M$3:$M$800,"NOT_FOUND") -> 19 | C8: 확인 범위에서 찾지 못함
A9: NOT_APPLICABLE | B9: =COUNTIFS(gold_values!$AO$3:$AO$800,"Y",gold_values!$L$3:$L$800,"CORE",gold_values!$M$3:$M$800,"NOT_APPLICABLE") -> 0 | C9: 해당 없음
A10: PENDING | B10: =COUNTIFS(gold_values!$AO$3:$AO$800,"Y",gold_values!$L$3:$L$800,"CORE",gold_values!$M$3:$M$800,"PENDING") -> 1 | C10: 사람 판정 필요
A11: 라벨 진행률 | B11: =IF(B5=0,"-",1-B10/B5) -> 0.9921875 | C11: PENDING이 아닌 칸 비율
A12: 필드 충족률 | B12: =IF((B6+B7+B8)=0,"-",B6/(B6+B7+B8)) -> 0.8503937 | C12: REPORTED ÷ (REPORTED+REDACTED+NOT_FOUND)
A15: 시험별
A16: 구분 | B16: 전체 | C16: REPORTED | D16: REDACTED | E16: NOT_FOUND | F16: NOT_APPLICABLE | G16: PENDING | H16: 충족률
A17: ST_SB17_1001 | B17: =COUNTIFS(gold_values!$AO$3:$AO$800,"Y",gold_values!$L$3:$L$800,"CORE",gold_values!$C$3:$C$800,A17) -> 32 | C17: =COUNTIFS(gold_values!$AO$3:$AO$800,"Y",gold_values!$L$3:$L$800,"CORE",gold_values!$C$3:$C$800,A17,gold_values!$M$3:$M$800,"REPORTED") -> 22 | D17: =COUNTIFS(gold_values!$AO$3:$AO$800,"Y",gold_values!$L$3:$L$800,"CORE",gold_values!$C$3:$C$800,A17,gold_values!$M$3:$M$800,"REDACTED") -> 0 | E17: =COUNTIFS(gold_values!$AO$3:$AO$800,"Y",gold_values!$L$3:$L$800,"CORE",gold_values!$C$3:$C$800,A17,gold_values!$M$3:$M$800,"NOT_FOUND") -> 10 | F17: =COUNTIFS(gold_values!$AO$3:$AO$800,"Y",gold_values!$L$3:$L$800,"CORE",gold_values!$C$3:$C$800,A17,gold_values!$M$3:$M$800,"NOT_APPLICABLE") -> 0 | G17: =COUNTIFS(gold_values!$AO$3:$AO$800,"Y",gold_values!$L$3:$L$800,"CORE",gold_values!$C$3:$C$800,A17,gold_values!$M$3:$M$800,"PENDING") -> 0 | H17: =IF((C17+D17+E17)=0,"-",C17/(C17+D17+E17)) -> 0.6875
A18: ST_ABP_20190230 | B18: =COUNTIFS(gold_values!$AO$3:$AO$800,"Y",gold_values!$L$3:$L$800,"CORE",gold_values!$C$3:$C$800,A18) -> 32 | C18: =COUNTIFS(gold_values!$AO$3:$AO$800,"Y",gold_values!$L$3:$L$800,"CORE",gold_values!$C$3:$C$800,A18,gold_values!$M$3:$M$800,"REPORTED") -> 29 | D18: =COUNTIFS(gold_values!$AO$3:$AO$800,"Y",gold_values!$L$3:$L$800,"CORE",gold_values!$C$3:$C$800,A18,gold_values!$M$3:$M$800,"REDACTED") -> 0 | E18: =COUNTIFS(gold_values!$AO$3:$AO$800,"Y",gold_values!$L$3:$L$800,"CORE",gold_values!$C$3:$C$800,A18,gold_values!$M$3:$M$800,"NOT_FOUND") -> 3 | F18: =COUNTIFS(gold_values!$AO$3:$AO$800,"Y",gold_values!$L$3:$L$800,"CORE",gold_values!$C$3:$C$800,A18,gold_values!$M$3:$M$800,"NOT_APPLICABLE") -> 0 | G18: =COUNTIFS(gold_values!$AO$3:$AO$800,"Y",gold_values!$L$3:$L$800,"CORE",gold_values!$C$3:$C$800,A18,gold_values!$M$3:$M$800,"PENDING") -> 0 | H18: =IF((C18+D18+E18)=0,"-",C18/(C18+D18+E18)) -> 0.90625
A19: ST_CTP43_1_1_P2 | B19: =COUNTIFS(gold_values!$AO$3:$AO$800,"Y",gold_values!$L$3:$L$800,"CORE",gold_values!$C$3:$C$800,A19) -> 32 | C19: =COUNTIFS(gold_values!$AO$3:$AO$800,"Y",gold_values!$L$3:$L$800,"CORE",gold_values!$C$3:$C$800,A19,gold_values!$M$3:$M$800,"REPORTED") -> 28 | D19: =COUNTIFS(gold_values!$AO$3:$AO$800,"Y",gold_values!$L$3:$L$800,"CORE",gold_values!$C$3:$C$800,A19,gold_values!$M$3:$M$800,"REDACTED") -> 0 | E19: =COUNTIFS(gold_values!$AO$3:$AO$800,"Y",gold_values!$L$3:$L$800,"CORE",gold_values!$C$3:$C$800,A19,gold_values!$M$3:$M$800,"NOT_FOUND") -> 3 | F19: =COUNTIFS(gold_values!$AO$3:$AO$800,"Y",gold_values!$L$3:$L$800,"CORE",gold_values!$C$3:$C$800,A19,gold_values!$M$3:$M$800,"NOT_APPLICABLE") -> 0 | G19: =COUNTIFS(gold_values!$AO$3:$AO$800,"Y",gold_values!$L$3:$L$800,"CORE",gold_values!$C$3:$C$800,A19,gold_values!$M$3:$M$800,"PENDING") -> 1 | H19: =IF((C19+D19+E19)=0,"-",C19/(C19+D19+E19)) -> 0.90322581
A20: ST_CTP43_1_2 | B20: =COUNTIFS(gold_values!$AO$3:$AO$800,"Y",gold_values!$L$3:$L$800,"CORE",gold_values!$C$3:$C$800,A20) -> 32 | C20: =COUNTIFS(gold_values!$AO$3:$AO$800,"Y",gold_values!$L$3:$L$800,"CORE",gold_values!$C$3:$C$800,A20,gold_values!$M$3:$M$800,"REPORTED") -> 29 | D20: =COUNTIFS(gold_values!$AO$3:$AO$800,"Y",gold_values!$L$3:$L$800,"CORE",gold_values!$C$3:$C$800,A20,gold_values!$M$3:$M$800,"REDACTED") -> 0 | E20: =COUNTIFS(gold_values!$AO$3:$AO$800,"Y",gold_values!$L$3:$L$800,"CORE",gold_values!$C$3:$C$800,A20,gold_values!$M$3:$M$800,"NOT_FOUND") -> 3 | F20: =COUNTIFS(gold_values!$AO$3:$AO$800,"Y",gold_values!$L$3:$L$800,"CORE",gold_values!$C$3:$C$800,A20,gold_values!$M$3:$M$800,"NOT_APPLICABLE") -> 0 | G20: =COUNTIFS(gold_values!$AO$3:$AO$800,"Y",gold_values!$L$3:$L$800,"CORE",gold_values!$C$3:$C$800,A20,gold_values!$M$3:$M$800,"PENDING") -> 0 | H20: =IF((C20+D20+E20)=0,"-",C20/(C20+D20+E20)) -> 0.90625
A22: 도메인별
A23: 구분 | B23: 전체 | C23: REPORTED | D23: REDACTED | E23: NOT_FOUND | F23: NOT_APPLICABLE | G23: PENDING | H23: 충족률
A24: DESIGN | B24: =COUNTIFS(gold_values!$AO$3:$AO$800,"Y",gold_values!$L$3:$L$800,"CORE",gold_values!$E$3:$E$800,A24) -> 52 | C24: =COUNTIFS(gold_values!$AO$3:$AO$800,"Y",gold_values!$L$3:$L$800,"CORE",gold_values!$E$3:$E$800,A24,gold_values!$M$3:$M$800,"REPORTED") -> 49 | D24: =COUNTIFS(gold_values!$AO$3:$AO$800,"Y",gold_values!$L$3:$L$800,"CORE",gold_values!$E$3:$E$800,A24,gold_values!$M$3:$M$800,"REDACTED") -> 0 | E24: =COUNTIFS(gold_values!$AO$3:$AO$800,"Y",gold_values!$L$3:$L$800,"CORE",gold_values!$E$3:$E$800,A24,gold_values!$M$3:$M$800,"NOT_FOUND") -> 3 | F24: =COUNTIFS(gold_values!$AO$3:$AO$800,"Y",gold_values!$L$3:$L$800,"CORE",gold_values!$E$3:$E$800,A24,gold_values!$M$3:$M$800,"NOT_APPLICABLE") -> 0 | G24: =COUNTIFS(gold_values!$AO$3:$AO$800,"Y",gold_values!$L$3:$L$800,"CORE",gold_values!$E$3:$E$800,A24,gold_values!$M$3:$M$800,"PENDING") -> 0 | H24: =IF((C24+D24+E24)=0,"-",C24/(C24+D24+E24)) -> 0.94230769
A25: PK | B25: =COUNTIFS(gold_values!$AO$3:$AO$800,"Y",gold_values!$L$3:$L$800,"CORE",gold_values!$E$3:$E$800,A25) -> 48 | C25: =COUNTIFS(gold_values!$AO$3:$AO$800,"Y",gold_values!$L$3:$L$800,"CORE",gold_values!$E$3:$E$800,A25,gold_values!$M$3:$M$800,"REPORTED") -> 34 | D25: =COUNTIFS(gold_values!$AO$3:$AO$800,"Y",gold_values!$L$3:$L$800,"CORE",gold_values!$E$3:$E$800,A25,gold_values!$M$3:$M$800,"REDACTED") -> 0 | E25: =COUNTIFS(gold_values!$AO$3:$AO$800,"Y",gold_values!$L$3:$L$800,"CORE",gold_values!$E$3:$E$800,A25,gold_values!$M$3:$M$800,"NOT_FOUND") -> 13 | F25: =COUNTIFS(gold_values!$AO$3:$AO$800,"Y",gold_values!$L$3:$L$800,"CORE",gold_values!$E$3:$E$800,A25,gold_values!$M$3:$M$800,"NOT_APPLICABLE") -> 0 | G25: =COUNTIFS(gold_values!$AO$3:$AO$800,"Y",gold_values!$L$3:$L$800,"CORE",gold_values!$E$3:$E$800,A25,gold_values!$M$3:$M$800,"PENDING") -> 1 | H25: =IF((C25+D25+E25)=0,"-",C25/(C25+D25+E25)) -> 0.72340426
A26: IMMUNO | B26: =COUNTIFS(gold_values!$AO$3:$AO$800,"Y",gold_values!$L$3:$L$800,"CORE",gold_values!$E$3:$E$800,A26) -> 28 | C26: =COUNTIFS(gold_values!$AO$3:$AO$800,"Y",gold_values!$L$3:$L$800,"CORE",gold_values!$E$3:$E$800,A26,gold_values!$M$3:$M$800,"REPORTED") -> 25 | D26: =COUNTIFS(gold_values!$AO$3:$AO$800,"Y",gold_values!$L$3:$L$800,"CORE",gold_values!$E$3:$E$800,A26,gold_values!$M$3:$M$800,"REDACTED") -> 0 | E26: =COUNTIFS(gold_values!$AO$3:$AO$800,"Y",gold_values!$L$3:$L$800,"CORE",gold_values!$E$3:$E$800,A26,gold_values!$M$3:$M$800,"NOT_FOUND") -> 3 | F26: =COUNTIFS(gold_values!$AO$3:$AO$800,"Y",gold_values!$L$3:$L$800,"CORE",gold_values!$E$3:$E$800,A26,gold_values!$M$3:$M$800,"NOT_APPLICABLE") -> 0 | G26: =COUNTIFS(gold_values!$AO$3:$AO$800,"Y",gold_values!$L$3:$L$800,"CORE",gold_values!$E$3:$E$800,A26,gold_values!$M$3:$M$800,"PENDING") -> 0 | H26: =IF((C26+D26+E26)=0,"-",C26/(C26+D26+E26)) -> 0.89285714
A28: 검증 지표 (EXAMPLE 제외 전체 행)
A29: 지표 | B29: 값 | C29: 설명
A30: 텍스트 자동 대조 PASS | B30: =COUNTIFS(gold_values!$L$3:$L$800,"<>EXAMPLE",gold_values!$AD$3:$AD$800,"PASS") -> 94 | C30: 인용문·숫자가 인용 페이지 텍스트 층에 실제로 있음
A31: 텍스트 자동 대조 FAIL | B31: =COUNTIFS(gold_values!$L$3:$L$800,"<>EXAMPLE",gold_values!$AD$3:$AD$800,"FAIL*") -> 0 | C31: 0이어야 함
A32: 이미지 근거 (시각 확인 필요) | B32: =COUNTIFS(gold_values!$L$3:$L$800,"<>EXAMPLE",gold_values!$AD$3:$AD$800,"IMAGE*") -> 34 | C32: 자동 대조 불가 → B 검토 때 우선 확인
A33: B 일치율 | B33: =IF((COUNTIF(gold_values!$AJ$3:$AJ$800,"Y")+COUNTIF(gold_values!$AJ$3:$AJ$800,"N"))=0,"-",COUNTIF(gold_values!$AJ$3:$AJ$800,"Y")/(COUNTIF(gold_values!$AJ$3:$AJ$800,"Y")+COUNTIF(gold_values!$AJ$3:$AJ$800,"N"))) -> - | C33: B_status를 입력한 행 중 A와 일치 (B 입력 전에는 '-')
A34: 이전 파일럿 추출과 일치 | B34: =COUNTIF(gold_values!$AM$3:$AM$800,"Y")&" / "&(COUNTIF(gold_values!$AM$3:$AM$800,"Y")+COUNTIF(gold_values!$AM$3:$AM$800,"N")) -> 8 / 8 | C34: observations.jsonl 8건 재추출 대조
A35: 키·출처 오류 칸 | B35: =COUNTIF(gold_values!$AP$3:$AP$800,"*누락") -> 0 | C35: 0이어야 함
A36: AI_DRAFT 칸 | B36: =COUNTIF(gold_values!$AN$3:$AN$800,"AI_DRAFT") -> 147 | C36: 사람 검증 전 칸
A37: HUMAN 칸 | B37: =COUNTIF(gold_values!$AN$3:$AN$800,"HUMAN") -> 0 | C37: B 검증 후 승격

Sheet gold_values
A1: 키 | M1: 정답 값 | V1: 출처 | AD1: 검증
A2: gold_id | B2: product_id | C2: study_key | D2: field_id | E2: domain | F2: level | G2: analysis_id | H2: arm | I2: comparison | J2: analysis_set | K2: timepoint | L2: row_type | M2: status | N2: value_text | O2: value_num | P2: ci_low | Q2: ci_high | R2: unit | S2: n_test | T2: n_ref | U2: denominator | V2: source_id | W2: pdf_page | X2: printed_page | Y2: locator | Z2: modality | AA2: evidence_quote | AB2: alt_locations | AC2: searched_scope | AD2: auto_text_check | AE2: B_status | AF2: B_value_num | AG2: B_ci_low | AH2: B_ci_high | AI2: B_pdf_page | AJ2: agree | AK2: cross_source_id | AL2: cross_value | AM2: cross_match | AN2: gold_tier | AO2: in_eval | AP2: key_check | AQ2: notes
A3: G-EX-01 | B3: P_ABP654 | C3: ST_ABP_20200417 | D3: pk_gmr_auc_tau | E3: =IFERROR(INDEX(field_dictionary!$B:$B,MATCH($D3,field_dictionary!$A:$A,0)),"") -> PK | F3: =IFERROR(INDEX(field_dictionary!$C:$C,MATCH($D3,field_dictionary!$A:$A,0)),"") -> COMPARISON | G3: PRIMARY | H3: NA | I3: SWITCH_vs_CONT | K3: Week 52–64 | L3: EXAMPLE | M3: REPORTED | N3: 0.9325 (90% CI 0.8874–0.9799) | O3: 93.25 | P3: 88.74 | Q3: 97.99 | R3: % | V3: SRC_EUCTR_ABP_IC | Y3: Results > Primary end points | Z3: TEXT | AJ3: =IF(AE3="","",IF(AND(AE3=M3,ABS(N(AF3)-N(O3))<=0.01,ABS(N(AG3)-N(P3))<=0.01,ABS(N(AH3)-N(Q3))<=0.01),"Y","N")) | AM3: =IF(OR(AL3="",O3=""),"",IF(ABS(N(AL3)-N(O3))<=0.01,"Y","N")) | AO3: =IFERROR(INDEX(studies!$L:$L,MATCH($C3,studies!$A:$A,0)),"") -> N | AP3: =IF(AND(M3="REPORTED",V3=""),"출처 누락",IF(AND(M3="NOT_FOUND",AC3=""),"검색범위 누락",IF(F3="ARM",IF(OR(H3="",H3="NA"),"arm 누락","OK"),IF(F3="COMPARISON",IF(OR(I3="",I3="NA"),"비교쌍 누락",IF(OR(G3="",G3="NA"),"analysis_id 누락","OK")),IF(F3="","","OK"))))) -> OK | AQ3: 형식 예시(평가 제외). 20200417 상호교환성 시험 — Wezenla EPAR에 없는 시험. EU CTR 구조화 결과를 요약 도구로 조회(2026-10-02), 원문 문구 대조 필요
A4: G-EX-02 | B4: P_ABP654 | C4: ST_ABP_20200417 | D4: pk_gmr_cmax | E4: =IFERROR(INDEX(field_dictionary!$B:$B,MATCH($D4,field_dictionary!$A:$A,0)),"") -> PK | F4: =IFERROR(INDEX(field_dictionary!$C:$C,MATCH($D4,field_dictionary!$A:$A,0)),"") -> COMPARISON | G4: PRIMARY | H4: NA | I4: SWITCH_vs_CONT | K4: Week 52–64 | L4: EXAMPLE | M4: REPORTED | N4: 0.9483 (90% CI 0.8977–1.0018) | O4: 94.83 | P4: 89.77 | Q4: 100.18 | R4: % | V4: SRC_EUCTR_ABP_IC | Y4: Results > Primary end points | Z4: TEXT | AJ4: =IF(AE4="","",IF(AND(AE4=M4,ABS(N(AF4)-N(O4))<=0.01,ABS(N(AG4)-N(P4))<=0.01,ABS(N(AH4)-N(Q4))<=0.01),"Y","N")) | AM4: =IF(OR(AL4="",O4=""),"",IF(ABS(N(AL4)-N(O4))<=0.01,"Y","N")) | AO4: =IFERROR(INDEX(studies!$L:$L,MATCH($C4,studies!$A:$A,0)),"") -> N | AP4: =IF(AND(M4="REPORTED",V4=""),"출처 누락",IF(AND(M4="NOT_FOUND",AC4=""),"검색범위 누락",IF(F4="ARM",IF(OR(H4="",H4="NA"),"arm 누락","OK"),IF(F4="COMPARISON",IF(OR(I4="",I4="NA"),"비교쌍 누락",IF(OR(G4="",G4="NA"),"analysis_id 누락","OK")),IF(F4="","","OK"))))) -> OK | AQ4: 형식 예시(평가 제외). 20200417 상호교환성 시험 — Wezenla EPAR에 없는 시험. EU CTR 구조화 결과를 요약 도구로 조회(2026-10-02), 원문 문구 대조 필요
A5: G-SB17-001 | B5: P_SB17 | C5: ST_SB17_1001 | D5: design_phase | E5: =IFERROR(INDEX(field_dictionary!$B:$B,MATCH($D5,field_dictionary!$A:$A,0)),"") -> DESIGN | F5: =IFERROR(INDEX(field_dictionary!$C:$C,MATCH($D5,field_dictionary!$A:$A,0)),"") -> STUDY | G5: NA | H5: NA | I5: NA | J5: NA | L5: CORE | M5: REPORTED | N5: Phase I | O5: 1 | V5: SRC_EPAR_PYZ | W5: 37 | X5: Page 37/168 | Y5: 2.6.2.1 Study design | Z5: TEXT | AA5: randomised, double-blind, three-arm, parallel group, single-dose Phase I study | AD5: PASS | AJ5: =IF(AE5="","",IF(AND(AE5=M5,ABS(N(AF5)-N(O5))<=0.01,ABS(N(AG5)-N(P5))<=0.01,ABS(N(AH5)-N(Q5))<=0.01),"Y","N")) | AM5: =IF(OR(AL5="",O5=""),"",IF(ABS(N(AL5)-N(O5))<=0.01,"Y","N")) | AN5: AI_DRAFT | AO5: =IFERROR(INDEX(studies!$L:$L,MATCH($C5,studies!$A:$A,0)),"") -> Y | AP5: =IF(AND(M5="REPORTED",V5=""),"출처 누락",IF(AND(M5="NOT_FOUND",AC5=""),"검색범위 누락",IF(F5="ARM",IF(OR(H5="",H5="NA"),"arm 누락","OK"),IF(F5="COMPARISON",IF(OR(I5="",I5="NA"),"비교쌍 누락",IF(OR(G5="",G5="NA"),"analysis_id 누락","OK")),IF(F5="","","OK"))))) -> OK
A6: G-SB17-002 | B6: P_SB17 | C6: ST_SB17_1001 | D6: design_population | E6: =IFERROR(INDEX(field_dictionary!$B:$B,MATCH($D6,field_dictionary!$A:$A,0)),"") -> DESIGN | F6: =IFERROR(INDEX(field_dictionary!$C:$C,MATCH($D6,field_dictionary!$A:$A,0)),"") -> STUDY | G6: NA | H6: NA | I6: NA | J6: NA | L6: CORE | M6: REPORTED | N6: Healthy male or female, aged 18-55 years (inclusive); body weight 60.0-90.0 kg, BMI 19.0-29.9 kg/m2 | V6: SRC_EPAR_PYZ | W6: 38 | X6: Page 38/168 | Y6: Key inclusion criteria 1-2 | Z6: TEXT | AA6: Healthy male or female, aged 18-55 years (inclusive) on the day of signing the informed consent. | AD6: PASS | AJ6: =IF(AE6="","",IF(AND(AE6=M6,ABS(N(AF6)-N(O6))<=0.01,ABS(N(AG6)-N(P6))<=0.01,ABS(N(AH6)-N(Q6))<=0.01),"Y","N")) | AM6: =IF(OR(AL6="",O6=""),"",IF(ABS(N(AL6)-N(O6))<=0.01,"Y","N")) | AN6: AI_DRAFT | AO6: =IFERROR(INDEX(studies!$L:$L,MATCH($C6,studies!$A:$A,0)),"") -> Y | AP6: =IF(AND(M6="REPORTED",V6=""),"출처 누락",IF(AND(M6="NOT_FOUND",AC6=""),"검색범위 누락",IF(F6="ARM",IF(OR(H6="",H6="NA"),"arm 누락","OK"),IF(F6="COMPARISON",IF(OR(I6="",I6="NA"),"비교쌍 누락",IF(OR(G6="",G6="NA"),"analysis_id 누락","OK")),IF(F6="","","OK"))))) -> OK
A7: G-SB17-003 | B7: P_SB17 | C7: ST_SB17_1001 | D7: design_type | E7: =IFERROR(INDEX(field_dictionary!$B:$B,MATCH($D7,field_dictionary!$A:$A,0)),"") -> DESIGN | F7: =IFERROR(INDEX(field_dictionary!$C:$C,MATCH($D7,field_dictionary!$A:$A,0)),"") -> STUDY | G7: NA | H7: NA | I7: NA | J7: NA | L7: CORE | M7: REPORTED | N7: randomised, double-blind, three-arm, parallel group, single-dose | V7: SRC_EPAR_PYZ | W7: 37 | X7: Page 37/168 | Y7: 2.6.2.1 Study design | Z7: TEXT | AA7: Study SB17-1001 is a randomised, double-blind, three-arm, parallel group, single-dose Phase I study | AD7: PASS | AJ7: =IF(AE7="","",IF(AND(AE7=M7,ABS(N(AF7)-N(O7))<=0.01,ABS(N(AG7)-N(P7))<=0.01,ABS(N(AH7)-N(Q7))<=0.01),"Y","N")) | AM7: =IF(OR(AL7="",O7=""),"",IF(ABS(N(AL7)-N(O7))<=0.01,"Y","N")) | AN7: AI_DRAFT | AO7: =IFERROR(INDEX(studies!$L:$L,MATCH($C7,studies!$A:$A,0)),"") -> Y | AP7: =IF(AND(M7="REPORTED",V7=""),"출처 누락",IF(AND(M7="NOT_FOUND",AC7=""),"검색범위 누락",IF(F7="ARM",IF(OR(H7="",H7="NA"),"arm 누락","OK"),IF(F7="COMPARISON",IF(OR(I7="",I7="NA"),"비교쌍 누락",IF(OR(G7="",G7="NA"),"analysis_id 누락","OK")),IF(F7="","","OK"))))) -> OK
A8: G-SB17-004 | B8: P_SB17 | C8: ST_SB17_1001 | D8: dose | E8: =IFERROR(INDEX(field_dictionary!$B:$B,MATCH($D8,field_dictionary!$A:$A,0)),"") -> DESIGN | F8: =IFERROR(INDEX(field_dictionary!$C:$C,MATCH($D8,field_dictionary!$A:$A,0)),"") -> STUDY | G8: NA | H8: NA | I8: NA | J8: NA | L8: CORE | M8: REPORTED | N8: 45 mg/0.5 mL | O8: 45 | R8: mg | V8: SRC_EPAR_PYZ | W8: 39 | X8: Page 39/168 | Y8: Treatments | Z8: TEXT | AA8: Subjects received a single dose of 45 mg/0.5 mL of either Pyzchiva, EU-approved Stelara, or US- licensed Stelara on Day 1 as an SC injection. | AD8: PASS | AJ8: =IF(AE8="","",IF(AND(AE8=M8,ABS(N(AF8)-N(O8))<=0.01,ABS(N(AG8)-N(P8))<=0.01,ABS(N(AH8)-N(Q8))<=0.01),"Y","N")) | AM8: =IF(OR(AL8="",O8=""),"",IF(ABS(N(AL8)-N(O8))<=0.01,"Y","N")) | AN8: AI_DRAFT | AO8: =IFERROR(INDEX(studies!$L:$L,MATCH($C8,studies!$A:$A,0)),"") -> Y | AP8: =IF(AND(M8="REPORTED",V8=""),"출처 누락",IF(AND(M8="NOT_FOUND",AC8=""),"검색범위 누락",IF(F8="ARM",IF(OR(H8="",H8="NA"),"arm 누락","OK"),IF(F8="COMPARISON",IF(OR(I8="",I8="NA"),"비교쌍 누락",IF(OR(G8="",G8="NA"),"analysis_id 누락","OK")),IF(F8="","","OK"))))) -> OK
A9: G-SB17-005 | B9: P_SB17 | C9: ST_SB17_1001 | D9: route | E9: =IFERROR(INDEX(field_dictionary!$B:$B,MATCH($D9,field_dictionary!$A:$A,0)),"") -> DESIGN | F9: =IFERROR(INDEX(field_dictionary!$C:$C,MATCH($D9,field_dictionary!$A:$A,0)),"") -> STUDY | G9: NA | H9: NA | I9: NA | J9: NA | L9: CORE | M9: REPORTED | N9: SC | V9: SRC_EPAR_PYZ | W9: 39 | X9: Page 39/168 | Y9: Treatments | Z9: TEXT | AA9: on Day 1 as an SC injection | AD9: PASS | AJ9: =IF(AE9="","",IF(AND(AE9=M9,ABS(N(AF9)-N(O9))<=0.01,ABS(N(AG9)-N(P9))<=0.01,ABS(N(AH9)-N(Q9))<=0.01),"Y","N")) | AM9: =IF(OR(AL9="",O9=""),"",IF(ABS(N(AL9)-N(O9))<=0.01,"Y","N")) | AN9: AI_DRAFT | AO9: =IFERROR(INDEX(studies!$L:$L,MATCH($C9,studies!$A:$A,0)),"") -> Y | AP9: =IF(AND(M9="REPORTED",V9=""),"출처 누락",IF(AND(M9="NOT_FOUND",AC9=""),"검색범위 누락",IF(F9="ARM",IF(OR(H9="",H9="NA"),"arm 누락","OK"),IF(F9="COMPARISON",IF(OR(I9="",I9="NA"),"비교쌍 누락",IF(OR(G9="",G9="NA"),"analysis_id 누락","OK")),IF(F9="","","OK"))))) -> OK
A10: G-SB17-006 | B10: P_SB17 | C10: ST_SB17_1001 | D10: primary_pk_endpoints | E10: =IFERROR(INDEX(field_dictionary!$B:$B,MATCH($D10,field_dictionary!$A:$A,0)),"") -> DESIGN | F10: =IFERROR(INDEX(field_dictionary!$C:$C,MATCH($D10,field_dictionary!$A:$A,0)),"") -> STUDY | G10: NA | H10: NA | I10: NA | J10: NA | L10: CORE | M10: REPORTED | N10: Cmax; AUC0-inf | V10: SRC_EPAR_PYZ | W10: 39 | X10: Page 39/168 | Y10: Primary endpoints | Z10: TEXT | AA10: Maximum serum concentration (Cmax) AND area under the serum concentration-time curve from time zero extrapolated to infinity (AUC0-inf) | AD10: PASS | AJ10: =IF(AE10="","",IF(AND(AE10=M10,ABS(N(AF10)-N(O10))<=0.01,ABS(N(AG10)-N(P10))<=0.01,ABS(N(AH10)-N(Q10))<=0.01),"Y","N")) | AM10: =IF(OR(AL10="",O10=""),"",IF(ABS(N(AL10)-N(O10))<=0.01,"Y","N")) | AN10: AI_DRAFT | AO10: =IFERROR(INDEX(studies!$L:$L,MATCH($C10,studies!$A:$A,0)),"") -> Y | AP10: =IF(AND(M10="REPORTED",V10=""),"출처 누락",IF(AND(M10="NOT_FOUND",AC10=""),"검색범위 누락",IF(F10="ARM",IF(OR(H10="",H10="NA"),"arm 누락","OK"),IF(F10="COMPARISON",IF(OR(I10="",I10="NA"),"비교쌍 누락",IF(OR(G10="",G10="NA"),"analysis_id 누락","OK")),IF(F10="","","OK"))))) -> OK
A11: G-SB17-007 | B11: P_SB17 | C11: ST_SB17_1001 | D11: equiv_margin | E11: =IFERROR(INDEX(field_dictionary!$B:$B,MATCH($D11,field_dictionary!$A:$A,0)),"") -> DESIGN | F11: =IFERROR(INDEX(field_dictionary!$C:$C,MATCH($D11,field_dictionary!$A:$A,0)),"") -> STUDY | G11: NA | H11: NA | I11: NA | J11: NA | L11: CORE | M11: REPORTED | N11: 0.8 to 1.25 (80% to 125%) | R11: ratio | V11: SRC_EPAR_PYZ | W11: 39 | X11: Page 39/168 | Y11: Objectives | Z11: TEXT | AA11: entirely contained within the equivalence margin of 0.8 to 1.25 | AD11: PASS | AJ11: =IF(AE11="","",IF(AND(AE11=M11,ABS(N(AF11)-N(O11))<=0.01,ABS(N(AG11)-N(P11))<=0.01,ABS(N(AH11)-N(Q11))<=0.01),"Y","N")) | AM11: =IF(OR(AL11="",O11=""),"",IF(ABS(N(AL11)-N(O11))<=0.01,"Y","N")) | AN11: AI_DRAFT | AO11: =IFERROR(INDEX(studies!$L:$L,MATCH($C11,studies!$A:$A,0)),"") -> Y | AP11: =IF(AND(M11="REPORTED",V11=""),"출처 누락",IF(AND(M11="NOT_FOUND",AC11=""),"검색범위 누락",IF(F11="ARM",IF(OR(H11="",H11="NA"),"arm 누락","OK"),IF(F11="COMPARISON",IF(OR(I11="",I11="NA"),"비교쌍 누락",IF(OR(G11="",G11="NA"),"analysis_id 누락","OK")),IF(F11="","","OK"))))) -> OK | AQ11: EMA 심사는 SB17 vs EU 비교만 1차 판정 기준(p41). US 관련 비교는 FDA용.
A12: G-SB17-008 | B12: P_SB17 | C12: ST_SB17_1001 | D12: ada_assay | E12: =IFERROR(INDEX(field_dictionary!$B:$B,MATCH($D12,field_dictionary!$A:$A,0)),"") -> IMMUNO | F12: =IFERROR(INDEX(field_dictionary!$C:$C,MATCH($D12,field_dictionary!$A:$A,0)),"") -> STUDY | G12: NA | H12: NA | I12: NA | J12: NA | L12: CORE | M12: REPORTED | N12: ADA: bridging ligand-binding assay, ECL (MSD), three-tiered. NAb: competitive ligand-binding assay, ECL (MSD) | V12: SRC_EPAR_PYZ | W12: 42 | X12: Page 42/168 | Y12: ADA assay / NAb assay | Z12: TEXT | AA12: using a bridging ligand-binding assay with an electrochemiluminescence (ECL) platform with Mesoscale Discovery (MSD) | AB12: p42 NAb assay 문단 | AD12: PASS | AJ12: =IF(AE12="","",IF(AND(AE12=M12,ABS(N(AF12)-N(O12))<=0.01,ABS(N(AG12)-N(P12))<=0.01,ABS(N(AH12)-N(Q12))<=0.01),"Y","N")) | AM12: =IF(OR(AL12="",O12=""),"",IF(ABS(N(AL12)-N(O12))<=0.01,"Y","N")) | AN12: AI_DRAFT | AO12: =IFERROR(INDEX(studies!$L:$L,MATCH($C12,studies!$A:$A,0)),"") -> Y | AP12: =IF(AND(M12="REPORTED",V12=""),"출처 누락",IF(AND(M12="NOT_FOUND",AC12=""),"검색범위 누락",IF(F12="ARM",IF(OR(H12="",H12="NA"),"arm 누락","OK"),IF(F12="COMPARISON",IF(OR(I12="",I12="NA"),"비교쌍 누락",IF(OR(G12="",G12="NA"),"analysis_id 누락","OK")),IF(F12="","","OK"))))) -> OK
A13: G-SB17-009 | B13: P_SB17 | C13: ST_SB17_1001 | D13: n_randomized | E13: =IFERROR(INDEX(field_dictionary!$B:$B,MATCH($D13,field_dictionary!$A:$A,0)),"") -> DESIGN | F13: =IFERROR(INDEX(field_dictionary!$C:$C,MATCH($D13,field_dictionary!$A:$A,0)),"") -> ARM | G13: NA | H13: TEST | I13: NA | J13: RANDOMIZED | L13: CORE | M13: REPORTED | N13: 67 | O13: 67 | R13: 명 | V13: SRC_EPAR_PYZ | W13: 42 | X13: Page 42/168 | Y13: Patient flow | Z13: TEXT | AA13: 201 subjects (67 subjects in each Pyzchiva, EU Stelara, and US Stelara) were randomised | AB13: p43 Table 3 (이미지) | AD13: PASS | AJ13: =IF(AE13="","",IF(AND(AE13=M13,ABS(N(AF13)-N(O13))<=0.01,ABS(N(AG13)-N(P13))<=0.01,ABS(N(AH13)-N(Q13))<=0.01),"Y","N")) | AM13: =IF(OR(AL13="",O13=""),"",IF(ABS(N(AL13)-N(O13))<=0.01,"Y","N")) | AN13: AI_DRAFT | AO13: =IFERROR(INDEX(studies!$L:$L,MATCH($C13,studies!$A:$A,0)),"") -> Y | AP13: =IF(AND(M13="REPORTED",V13=""),"출처 누락",IF(AND(M13="NOT_FOUND",AC13=""),"검색범위 누락",IF(F13="ARM",IF(OR(H13="",H13="NA"),"arm 누락","OK"),IF(F13="COMPARISON",IF(OR(I13="",I13="NA"),"비교쌍 누락",IF(OR(G13="",G13="NA"),"analysis_id 누락","OK")),IF(F13="","","OK"))))) -> OK
A14: G-SB17-010 | B14: P_SB17 | C14: ST_SB17_1001 | D14: n_randomized | E14: =IFERROR(INDEX(field_dictionary!$B:$B,MATCH($D14,field_dictionary!$A:$A,0)),"") -> DESIGN | F14: =IFERROR(INDEX(field_dictionary!$C:$C,MATCH($D14,field_dictionary!$A:$A,0)),"") -> ARM | G14: NA | H14: EU_RP | I14: NA | J14: RANDOMIZED | L14: CORE | M14: REPORTED | N14: 67 | O14: 67 | R14: 명 | V14: SRC_EPAR_PYZ | W14: 42 | X14: Page 42/168 | Y14: Patient flow | Z14: TEXT | AA14: 201 subjects (67 subjects in each Pyzchiva, EU Stelara, and US Stelara) were randomised | AB14: p43 Table 3 (이미지) | AD14: PASS | AJ14: =IF(AE14="","",IF(AND(AE14=M14,ABS(N(AF14)-N(O14))<=0.01,ABS(N(AG14)-N(P14))<=0.01,ABS(N(AH14)-N(Q14))<=0.01),"Y","N")) | AM14: =IF(OR(AL14="",O14=""),"",IF(ABS(N(AL14)-N(O14))<=0.01,"Y","N")) | AN14: AI_DRAFT | AO14: =IFERROR(INDEX(studies!$L:$L,MATCH($C14,studies!$A:$A,0)),"") -> Y | AP14: =IF(AND(M14="REPORTED",V14=""),"출처 누락",IF(AND(M14="NOT_FOUND",AC14=""),"검색범위 누락",IF(F14="ARM",IF(OR(H14="",H14="NA"),"arm 누락","OK"),IF(F14="COMPARISON",IF(OR(I14="",I14="NA"),"비교쌍 누락",IF(OR(G14="",G14="NA"),"analysis_id 누락","OK")),IF(F14="","","OK"))))) -> OK
A15: G-SB17-011 | B15: P_SB17 | C15: ST_SB17_1001 | D15: n_randomized | E15: =IFERROR(INDEX(field_dictionary!$B:$B,MATCH($D15,field_dictionary!$A:$A,0)),"") -> DESIGN | F15: =IFERROR(INDEX(field_dictionary!$C:$C,MATCH($D15,field_dictionary!$A:$A,0)),"") -> ARM | G15: NA | H15: US_RP | I15: NA | J15: RANDOMIZED | L15: CORE | M15: REPORTED | N15: 67 | O15: 67 | R15: 명 | V15: SRC_EPAR_PYZ | W15: 42 | X15: Page 42/168 | Y15: Patient flow | Z15: TEXT | AA15: 201 subjects (67 subjects in each Pyzchiva, EU Stelara, and US Stelara) were randomised | AB15: p43 Table 3 (이미지) | AD15: PASS | AJ15: =IF(AE15="","",IF(AND(AE15=M15,ABS(N(AF15)-N(O15))<=0.01,ABS(N(AG15)-N(P15))<=0.01,ABS(N(AH15)-N(Q15))<=0.01),"Y","N")) | AM15: =IF(OR(AL15="",O15=""),"",IF(ABS(N(AL15)-N(O15))<=0.01,"Y","N")) | AN15: AI_DRAFT | AO15: =IFERROR(INDEX(studies!$L:$L,MATCH($C15,studies!$A:$A,0)),"") -> Y | AP15: =IF(AND(M15="REPORTED",V15=""),"출처 누락",IF(AND(M15="NOT_FOUND",AC15=""),"검색범위 누락",IF(F15="ARM",IF(OR(H15="",H15="NA"),"arm 누락","OK"),IF(F15="COMPARISON",IF(OR(I15="",I15="NA"),"비교쌍 누락",IF(OR(G15="",G15="NA"),"analysis_id 누락","OK")),IF(F15="","","OK"))))) -> OK
A16: G-SB17-012 | B16: P_SB17 | C16: ST_SB17_1001 | D16: n_pk_set | E16: =IFERROR(INDEX(field_dictionary!$B:$B,MATCH($D16,field_dictionary!$A:$A,0)),"") -> DESIGN | F16: =IFERROR(INDEX(field_dictionary!$C:$C,MATCH($D16,field_dictionary!$A:$A,0)),"") -> ARM | G16: NA | H16: TEST | I16: NA | J16: PK_SET | L16: CORE | M16: REPORTED | N16: 67 | O16: 67 | R16: 명 | V16: SRC_EPAR_PYZ | W16: 42 | X16: Page 42/168 | Y16: Patient flow | Z16: TEXT | AA16: were randomised, all of whom included in the SAF and PKS | AB16: p43 Table 3 (이미지), p47 Table 8 'N = 67' | AD16: PASS | AJ16: =IF(AE16="","",IF(AND(AE16=M16,ABS(N(AF16)-N(O16))<=0.01,ABS(N(AG16)-N(P16))<=0.01,ABS(N(AH16)-N(Q16))<=0.01),"Y","N")) | AM16: =IF(OR(AL16="",O16=""),"",IF(ABS(N(AL16)-N(O16))<=0.01,"Y","N")) | AN16: AI_DRAFT | AO16: =IFERROR(INDEX(studies!$L:$L,MATCH($C16,studies!$A:$A,0)),"") -> Y | AP16: =IF(AND(M16="REPORTED",V16=""),"출처 누락",IF(AND(M16="NOT_FOUND",AC16=""),"검색범위 누락",IF(F16="ARM",IF(OR(H16="",H16="NA"),"arm 누락","OK"),IF(F16="COMPARISON",IF(OR(I16="",I16="NA"),"비교쌍 누락",IF(OR(G16="",G16="NA"),"analysis_id 누락","OK")),IF(F16="","","OK"))))) -> OK | AQ16: PKS N=67이지만 평가변수별 실제 분석 n은 62/64/60 → GMR 행의 n_test/n_ref 참조
A17: G-SB17-013 | B17: P_SB17 | C17: ST_SB17_1001 | D17: n_pk_set | E17: =IFERROR(INDEX(field_dictionary!$B:$B,MATCH($D17,field_dictionary!$A:$A,0)),"") -> DESIGN | F17: =IFERROR(INDEX(field_dictionary!$C:$C,MATCH($D17,field_dictionary!$A:$A,0)),"") -> ARM | G17: NA | H17: EU_RP | I17: NA | J17: PK_SET | L17: CORE | M17: REPORTED | N17: 67 | O17: 67 | R17: 명 | V17: SRC_EPAR_PYZ | W17: 42 | X17: Page 42/168 | Y17: Patient flow | Z17: TEXT | AA17: were randomised, all of whom included in the SAF and PKS | AB17: p43 Table 3 (이미지), p47 Table 8 'N = 67' | AD17: PASS | AJ17: =IF(AE17="","",IF(AND(AE17=M17,ABS(N(AF17)-N(O17))<=0.01,ABS(N(AG17)-N(P17))<=0.01,ABS(N(AH17)-N(Q17))<=0.01),"Y","N")) | AM17: =IF(OR(AL17="",O17=""),"",IF(ABS(N(AL17)-N(O17))<=0.01,"Y","N")) | AN17: AI_DRAFT | AO17: =IFERROR(INDEX(studies!$L:$L,MATCH($C17,studies!$A:$A,0)),"") -> Y | AP17: =IF(AND(M17="REPORTED",V17=""),"출처 누락",IF(AND(M17="NOT_FOUND",AC17=""),"검색범위 누락",IF(F17="ARM",IF(OR(H17="",H17="NA"),"arm 누락","OK"),IF(F17="COMPARISON",IF(OR(I17="",I17="NA"),"비교쌍 누락",IF(OR(G17="",G17="NA"),"analysis_id 누락","OK")),IF(F17="","","OK"))))) -> OK | AQ17: PKS N=67이지만 평가변수별 실제 분석 n은 62/64/60 → GMR 행의 n_test/n_ref 참조
A18: G-SB17-014 | B18: P_SB17 | C18: ST_SB17_1001 | D18: n_pk_set | E18: =IFERROR(INDEX(field_dictionary!$B:$B,MATCH($D18,field_dictionary!$A:$A,0)),"") -> DESIGN | F18: =IFERROR(INDEX(field_dictionary!$C:$C,MATCH($D18,field_dictionary!$A:$A,0)),"") -> ARM | G18: NA | H18: US_RP | I18: NA | J18: PK_SET | L18: CORE | M18: REPORTED | N18: 67 | O18: 67 | R18: 명 | V18: SRC_EPAR_PYZ | W18: 42 | X18: Page 42/168 | Y18: Patient flow | Z18: TEXT | AA18: were randomised, all of whom included in the SAF and PKS | AB18: p43 Table 3 (이미지), p47 Table 8 'N = 67' | AD18: PASS | AJ18: =IF(AE18="","",IF(AND(AE18=M18,ABS(N(AF18)-N(O18))<=0.01,ABS(N(AG18)-N(P18))<=0.01,ABS(N(AH18)-N(Q18))<=0.01),"Y","N")) | AM18: =IF(OR(AL18="",O18=""),"",IF(ABS(N(AL18)-N(O18))<=0.01,"Y","N")) | AN18: AI_DRAFT | AO18: =IFERROR(INDEX(studies!$L:$L,MATCH($C18,studies!$A:$A,0)),"") -> Y | AP18: =IF(AND(M18="REPORTED",V18=""),"출처 누락",IF(AND(M18="NOT_FOUND",AC18=""),"검색범위 누락",IF(F18="ARM",IF(OR(H18="",H18="NA"),"arm 누락","OK"),IF(F18="COMPARISON",IF(OR(I18="",I18="NA"),"비교쌍 누락",IF(OR(G18="",G18="NA"),"analysis_id 누락","OK")),IF(F18="","","OK"))))) -> OK | AQ18: PKS N=67이지만 평가변수별 실제 분석 n은 62/64/60 → GMR 행의 n_test/n_ref 참조
A19: G-SB17-015 | B19: P_SB17 | C19: ST_SB17_1001 | D19: ada_incidence | E19: =IFERROR(INDEX(field_dictionary!$B:$B,MATCH($D19,field_dictionary!$A:$A,0)),"") -> IMMUNO | F19: =IFERROR(INDEX(field_dictionary!$C:$C,MATCH($D19,field_dictionary!$A:$A,0)),"") -> ARM | G19: ADA_POSTDOSE_ANY | H19: TEST | I19: NA | J19: SAFETY_SET | K19: Post-dose (Day 29/71/99) | L19: CORE | M19: REPORTED | N19: 18/67 (26.9%) | O19: 26.9 | R19: % | U19: ALL_SUBJECTS (N=67) | V19: SRC_EPAR_PYZ | W19: 50 | X19: Page 50/168 | Y19: Immunogenicity | Z19: TEXT | AA19: The overall incidence of subjects with positive post-dose ADA to ustekinumab was 18/67 (26.9%), 23/67 (34.3%), and 23/67 (34.3%) | AB19: p49 Table 9 'Post-dose' 행 (이미지) | AD19: PASS | AJ19: =IF(AE19="","",IF(AND(AE19=M19,ABS(N(AF19)-N(O19))<=0.01,ABS(N(AG19)-N(P19))<=0.01,ABS(N(AH19)-N(Q19))<=0.01),"Y","N")) | AM19: =IF(OR(AL19="",O19=""),"",IF(ABS(N(AL19)-N(O19))<=0.01,"Y","N")) | AN19: AI_DRAFT | AO19: =IFERROR(INDEX(studies!$L:$L,MATCH($C19,studies!$A:$A,0)),"") -> Y | AP19: =IF(AND(M19="REPORTED",V19=""),"출처 누락",IF(AND(M19="NOT_FOUND",AC19=""),"검색범위 누락",IF(F19="ARM",IF(OR(H19="",H19="NA"),"arm 누락","OK"),IF(F19="COMPARISON",IF(OR(I19="",I19="NA"),"비교쌍 누락",IF(OR(G19="",G19="NA"),"analysis_id 누락","OK")),IF(F19="","","OK"))))) -> OK | AQ19: 정의: 기저치 이후 1회 이상 ADA 양성(기저치 양성 여부 무관)
A20: G-SB17-016 | B20: P_SB17 | C20: ST_SB17_1001 | D20: ada_incidence | E20: =IFERROR(INDEX(field_dictionary!$B:$B,MATCH($D20,field_dictionary!$A:$A,0)),"") -> IMMUNO | F20: =IFERROR(INDEX(field_dictionary!$C:$C,MATCH($D20,field_dictionary!$A:$A,0)),"") -> ARM | G20: ADA_POSTDOSE_ANY | H20: EU_RP | I20: NA | J20: SAFETY_SET | K20: Post-dose (Day 29/71/99) | L20: CORE | M20: REPORTED | N20: 23/67 (34.3%) | O20: 34.3 | R20: % | U20: ALL_SUBJECTS (N=67) | V20: SRC_EPAR_PYZ | W20: 50 | X20: Page 50/168 | Y20: Immunogenicity | Z20: TEXT | AA20: The overall incidence of subjects with positive post-dose ADA to ustekinumab was 18/67 (26.9%), 23/67 (34.3%), and 23/67 (34.3%) | AB20: p49 Table 9 'Post-dose' 행 (이미지) | AD20: PASS | AJ20: =IF(AE20="","",IF(AND(AE20=M20,ABS(N(AF20)-N(O20))<=0.01,ABS(N(AG20)-N(P20))<=0.01,ABS(N(AH20)-N(Q20))<=0.01),"Y","N")) | AM20: =IF(OR(AL20="",O20=""),"",IF(ABS(N(AL20)-N(O20))<=0.01,"Y","N")) | AN20: AI_DRAFT | AO20: =IFERROR(INDEX(studies!$L:$L,MATCH($C20,studies!$A:$A,0)),"") -> Y | AP20: =IF(AND(M20="REPORTED",V20=""),"출처 누락",IF(AND(M20="NOT_FOUND",AC20=""),"검색범위 누락",IF(F20="ARM",IF(OR(H20="",H20="NA"),"arm 누락","OK"),IF(F20="COMPARISON",IF(OR(I20="",I20="NA"),"비교쌍 누락",IF(OR(G20="",G20="NA"),"analysis_id 누락","OK")),IF(F20="","","OK"))))) -> OK | AQ20: 정의: 기저치 이후 1회 이상 ADA 양성(기저치 양성 여부 무관)
A21: G-SB17-017 | B21: P_SB17 | C21: ST_SB17_1001 | D21: ada_incidence | E21: =IFERROR(INDEX(field_dictionary!$B:$B,MATCH($D21,field_dictionary!$A:$A,0)),"") -> IMMUNO | F21: =IFERROR(INDEX(field_dictionary!$C:$C,MATCH($D21,field_dictionary!$A:$A,0)),"") -> ARM | G21: ADA_POSTDOSE_ANY | H21: US_RP | I21: NA | J21: SAFETY_SET | K21: Post-dose (Day 29/71/99) | L21: CORE | M21: REPORTED | N21: 23/67 (34.3%) | O21: 34.3 | R21: % | U21: ALL_SUBJECTS (N=67) | V21: SRC_EPAR_PYZ | W21: 50 | X21: Page 50/168 | Y21: Immunogenicity | Z21: TEXT | AA21: The overall incidence of subjects with positive post-dose ADA to ustekinumab was 18/67 (26.9%), 23/67 (34.3%), and 23/67 (34.3%) | AB21: p49 Table 9 'Post-dose' 행 (이미지) | AD21: PASS | AJ21: =IF(AE21="","",IF(AND(AE21=M21,ABS(N(AF21)-N(O21))<=0.01,ABS(N(AG21)-N(P21))<=0.01,ABS(N(AH21)-N(Q21))<=0.01),"Y","N")) | AM21: =IF(OR(AL21="",O21=""),"",IF(ABS(N(AL21)-N(O21))<=0.01,"Y","N")) | AN21: AI_DRAFT | AO21: =IFERROR(INDEX(studies!$L:$L,MATCH($C21,studies!$A:$A,0)),"") -> Y | AP21: =IF(AND(M21="REPORTED",V21=""),"출처 누락",IF(AND(M21="NOT_FOUND",AC21=""),"검색범위 누락",IF(F21="ARM",IF(OR(H21="",H21="NA"),"arm 누락","OK"),IF(F21="COMPARISON",IF(OR(I21="",I21="NA"),"비교쌍 누락",IF(OR(G21="",G21="NA"),"analysis_id 누락","OK")),IF(F21="","","OK"))))) -> OK | AQ21: 정의: 기저치 이후 1회 이상 ADA 양성(기저치 양성 여부 무관)
A22: G-SB17-018 | B22: P_SB17 | C22: ST_SB17_1001 | D22: nab_incidence | E22: =IFERROR(INDEX(field_dictionary!$B:$B,MATCH($D22,field_dictionary!$A:$A,0)),"") -> IMMUNO | F22: =IFERROR(INDEX(field_dictionary!$C:$C,MATCH($D22,field_dictionary!$A:$A,0)),"") -> ARM | G22: NAB_POSTDOSE_ANY | H22: TEST | I22: NA | J22: SAFETY_SET | K22: Post-dose overall | L22: CORE | M22: NOT_FOUND | V22: SRC_EPAR_PYZ | AC22: Pyzchiva EPAR 전체 텍스트 검색 + p49 Table 9(이미지) 확인: NAb는 시점별(Day 29/71/99)·ADA 양성자 분모로만 보고, 전체 기간 값 없음 | AD22: N/A | AJ22: =IF(AE22="","",IF(AND(AE22=M22,ABS(N(AF22)-N(O22))<=0.01,ABS(N(AG22)-N(P22))<=0.01,ABS(N(AH22)-N(Q22))<=0.01),"Y","N")) | AM22: =IF(OR(AL22="",O22=""),"",IF(ABS(N(AL22)-N(O22))<=0.01,"Y","N")) | AN22: AI_DRAFT | AO22: =IFERROR(INDEX(studies!$L:$L,MATCH($C22,studies!$A:$A,0)),"") -> Y | AP22: =IF(AND(M22="REPORTED",V22=""),"출처 누락",IF(AND(M22="NOT_FOUND",AC22=""),"검색범위 누락",IF(F22="ARM",IF(OR(H22="",H22="NA"),"arm 누락","OK"),IF(F22="COMPARISON",IF(OR(I22="",I22="NA"),"비교쌍 누락",IF(OR(G22="",G22="NA"),"analysis_id 누락","OK")),IF(F22="","","OK"))))) -> OK | AQ22: Day 99 시점 값은 EXTRA 행 참조
A23: G-SB17-019 | B23: P_SB17 | C23: ST_SB17_1001 | D23: nab_incidence | E23: =IFERROR(INDEX(field_dictionary!$B:$B,MATCH($D23,field_dictionary!$A:$A,0)),"") -> IMMUNO | F23: =IFERROR(INDEX(field_dictionary!$C:$C,MATCH($D23,field_dictionary!$A:$A,0)),"") -> ARM | G23: NAB_POSTDOSE_ANY | H23: EU_RP | I23: NA | J23: SAFETY_SET | K23: Post-dose overall | L23: CORE | M23: NOT_FOUND | V23: SRC_EPAR_PYZ | AC23: Pyzchiva EPAR 전체 텍스트 검색 + p49 Table 9(이미지) 확인: NAb는 시점별(Day 29/71/99)·ADA 양성자 분모로만 보고, 전체 기간 값 없음 | AD23: N/A | AJ23: =IF(AE23="","",IF(AND(AE23=M23,ABS(N(AF23)-N(O23))<=0.01,ABS(N(AG23)-N(P23))<=0.01,ABS(N(AH23)-N(Q23))<=0.01),"Y","N")) | AM23: =IF(OR(AL23="",O23=""),"",IF(ABS(N(AL23)-N(O23))<=0.01,"Y","N")) | AN23: AI_DRAFT | AO23: =IFERROR(INDEX(studies!$L:$L,MATCH($C23,studies!$A:$A,0)),"") -> Y | AP23: =IF(AND(M23="REPORTED",V23=""),"출처 누락",IF(AND(M23="NOT_FOUND",AC23=""),"검색범위 누락",IF(F23="ARM",IF(OR(H23="",H23="NA"),"arm 누락","OK"),IF(F23="COMPARISON",IF(OR(I23="",I23="NA"),"비교쌍 누락",IF(OR(G23="",G23="NA"),"analysis_id 누락","OK")),IF(F23="","","OK"))))) -> OK | AQ23: Day 99 시점 값은 EXTRA 행 참조
A24: G-SB17-020 | B24: P_SB17 | C24: ST_SB17_1001 | D24: nab_incidence | E24: =IFERROR(INDEX(field_dictionary!$B:$B,MATCH($D24,field_dictionary!$A:$A,0)),"") -> IMMUNO | F24: =IFERROR(INDEX(field_dictionary!$C:$C,MATCH($D24,field_dictionary!$A:$A,0)),"") -> ARM | G24: NAB_POSTDOSE_ANY | H24: US_RP | I24: NA | J24: SAFETY_SET | K24: Post-dose overall | L24: CORE | M24: NOT_FOUND | V24: SRC_EPAR_PYZ | AC24: Pyzchiva EPAR 전체 텍스트 검색 + p49 Table 9(이미지) 확인: NAb는 시점별(Day 29/71/99)·ADA 양성자 분모로만 보고, 전체 기간 값 없음 | AD24: N/A | AJ24: =IF(AE24="","",IF(AND(AE24=M24,ABS(N(AF24)-N(O24))<=0.01,ABS(N(AG24)-N(P24))<=0.01,ABS(N(AH24)-N(Q24))<=0.01),"Y","N")) | AM24: =IF(OR(AL24="",O24=""),"",IF(ABS(N(AL24)-N(O24))<=0.01,"Y","N")) | AN24: AI_DRAFT | AO24: =IFERROR(INDEX(studies!$L:$L,MATCH($C24,studies!$A:$A,0)),"") -> Y | AP24: =IF(AND(M24="REPORTED",V24=""),"출처 누락",IF(AND(M24="NOT_FOUND",AC24=""),"검색범위 누락",IF(F24="ARM",IF(OR(H24="",H24="NA"),"arm 누락","OK"),IF(F24="COMPARISON",IF(OR(I24="",I24="NA"),"비교쌍 누락",IF(OR(G24="",G24="NA"),"analysis_id 누락","OK")),IF(F24="","","OK"))))) -> OK | AQ24: Day 99 시점 값은 EXTRA 행 참조
A25: G-SB17-021 | B25: P_SB17 | C25: ST_SB17_1001 | D25: pk_gmr_auc_inf | E25: =IFERROR(INDEX(field_dictionary!$B:$B,MATCH($D25,field_dictionary!$A:$A,0)),"") -> PK | F25: =IFERROR(INDEX(field_dictionary!$C:$C,MATCH($D25,field_dictionary!$A:$A,0)),"") -> COMPARISON | G25: PRIMARY | H25: NA | I25: TEST_vs_EU_RP | J25: PK_SET | K25: Single dose | L25: CORE | M25: REPORTED | N25: 0.99 (90% CI 0.90; 1.08) | O25: 99 | P25: 90 | Q25: 108 | R25: % | S25: 62 | T25: 64 | V25: SRC_EPAR_PYZ | W25: 43 | X25: Page 43/168 | Y25: Table 4 | Z25: TEXT | AA25: 0.90; 1.08 | AB25: p45 Table 5 (이미지, 동일 값) | AD25: PASS | AJ25: =IF(AE25="","",IF(AND(AE25=M25,ABS(N(AF25)-N(O25))<=0.01,ABS(N(AG25)-N(P25))<=0.01,ABS(N(AH25)-N(Q25))<=0.01),"Y","N")) | AK25: PILOT_OBS | AL25: 99 | AM25: =IF(OR(AL25="",O25=""),"",IF(ABS(N(AL25)-N(O25))<=0.01,"Y","N")) -> Y | AN25: AI_DRAFT | AO25: =IFERROR(INDEX(studies!$L:$L,MATCH($C25,studies!$A:$A,0)),"") -> Y | AP25: =IF(AND(M25="REPORTED",V25=""),"출처 누락",IF(AND(M25="NOT_FOUND",AC25=""),"검색범위 누락",IF(F25="ARM",IF(OR(H25="",H25="NA"),"arm 누락","OK"),IF(F25="COMPARISON",IF(OR(I25="",I25="NA"),"비교쌍 누락",IF(OR(G25="",G25="NA"),"analysis_id 누락","OK")),IF(F25="","","OK"))))) -> OK | AQ25: 원문 scale=ratio. 1차 분석 = log 변환 ANOVA(p41)
A26: G-SB17-022 | B26: P_SB17 | C26: ST_SB17_1001 | D26: pk_gmr_auc_inf | E26: =IFERROR(INDEX(field_dictionary!$B:$B,MATCH($D26,field_dictionary!$A:$A,0)),"") -> PK | F26: =IFERROR(INDEX(field_dictionary!$C:$C,MATCH($D26,field_dictionary!$A:$A,0)),"") -> COMPARISON | G26: PRIMARY | H26: NA | I26: TEST_vs_US_RP | J26: PK_SET | K26: Single dose | L26: CORE | M26: NOT_FOUND | V26: SRC_EPAR_PYZ | AC26: p45 본문은 '90% CI가 기준 범위 안'이라고만 서술. 1차(ANOVA) 수치는 EPAR에 없음. 수치는 사후 ANCOVA(Table 7, p46)에만 있음 | AD26: N/A | AJ26: =IF(AE26="","",IF(AND(AE26=M26,ABS(N(AF26)-N(O26))<=0.01,ABS(N(AG26)-N(P26))<=0.01,ABS(N(AH26)-N(Q26))<=0.01),"Y","N")) | AM26: =IF(OR(AL26="",O26=""),"",IF(ABS(N(AL26)-N(O26))<=0.01,"Y","N")) | AN26: AI_DRAFT | AO26: =IFERROR(INDEX(studies!$L:$L,MATCH($C26,studies!$A:$A,0)),"") -> Y | AP26: =IF(AND(M26="REPORTED",V26=""),"출처 누락",IF(AND(M26="NOT_FOUND",AC26=""),"검색범위 누락",IF(F26="ARM",IF(OR(H26="",H26="NA"),"arm 누락","OK"),IF(F26="COMPARISON",IF(OR(I26="",I26="NA"),"비교쌍 누락",IF(OR(G26="",G26="NA"),"analysis_id 누락","OK")),IF(F26="","","OK"))))) -> OK | AQ26: 정성 결론은 pk_equiv_concluded 행에 기록
A27: G-SB17-023 | B27: P_SB17 | C27: ST_SB17_1001 | D27: pk_gmr_auc_inf | E27: =IFERROR(INDEX(field_dictionary!$B:$B,MATCH($D27,field_dictionary!$A:$A,0)),"") -> PK | F27: =IFERROR(INDEX(field_dictionary!$C:$C,MATCH($D27,field_dictionary!$A:$A,0)),"") -> COMPARISON | G27: PRIMARY | H27: NA | I27: EU_RP_vs_US_RP | J27: PK_SET | K27: Single dose | L27: CORE | M27: NOT_FOUND | V27: SRC_EPAR_PYZ | AC27: p45 본문은 '90% CI가 기준 범위 안'이라고만 서술. 1차(ANOVA) 수치는 EPAR에 없음. 수치는 사후 ANCOVA(Table 7, p46)에만 있음 | AD27: N/A | AJ27: =IF(AE27="","",IF(AND(AE27=M27,ABS(N(AF27)-N(O27))<=0.01,ABS(N(AG27)-N(P27))<=0.01,ABS(N(AH27)-N(Q27))<=0.01),"Y","N")) | AM27: =IF(OR(AL27="",O27=""),"",IF(ABS(N(AL27)-N(O27))<=0.01,"Y","N")) | AN27: AI_DRAFT | AO27: =IFERROR(INDEX(studies!$L:$L,MATCH($C27,studies!$A:$A,0)),"") -> Y | AP27: =IF(AND(M27="REPORTED",V27=""),"출처 누락",IF(AND(M27="NOT_FOUND",AC27=""),"검색범위 누락",IF(F27="ARM",IF(OR(H27="",H27="NA"),"arm 누락","OK"),IF(F27="COMPARISON",IF(OR(I27="",I27="NA"),"비교쌍 누락",IF(OR(G27="",G27="NA"),"analysis_id 누락","OK")),IF(F27="","","OK"))))) -> OK | AQ27: 정성 결론은 pk_equiv_concluded 행에 기록
A28: G-SB17-024 | B28: P_SB17 | C28: ST_SB17_1001 | D28: pk_gmr_cmax | E28: =IFERROR(INDEX(field_dictionary!$B:$B,MATCH($D28,field_dictionary!$A:$A,0)),"") -> PK | F28: =IFERROR(INDEX(field_dictionary!$C:$C,MATCH($D28,field_dictionary!$A:$A,0)),"") -> COMPARISON | G28: PRIMARY | H28: NA | I28: TEST_vs_EU_RP | J28: PK_SET | K28: Single dose | L28: CORE | M28: REPORTED | N28: 0.90 (90% CI 0.82; 0.98) | O28: 90 | P28: 82 | Q28: 98 | R28: % | S28: 62 | T28: 64 | V28: SRC_EPAR_PYZ | W28: 43 | X28: Page 43/168 | Y28: Table 4 | Z28: TEXT | AA28: 0.82; 0.98 | AB28: p45 Table 5 (이미지, 동일 값) | AD28: PASS | AJ28: =IF(AE28="","",IF(AND(AE28=M28,ABS(N(AF28)-N(O28))<=0.01,ABS(N(AG28)-N(P28))<=0.01,ABS(N(AH28)-N(Q28))<=0.01),"Y","N")) | AK28: PILOT_OBS | AL28: 90 | AM28: =IF(OR(AL28="",O28=""),"",IF(ABS(N(AL28)-N(O28))<=0.01,"Y","N")) -> Y | AN28: AI_DRAFT | AO28: =IFERROR(INDEX(studies!$L:$L,MATCH($C28,studies!$A:$A,0)),"") -> Y | AP28: =IF(AND(M28="REPORTED",V28=""),"출처 누락",IF(AND(M28="NOT_FOUND",AC28=""),"검색범위 누락",IF(F28="ARM",IF(OR(H28="",H28="NA"),"arm 누락","OK"),IF(F28="COMPARISON",IF(OR(I28="",I28="NA"),"비교쌍 누락",IF(OR(G28="",G28="NA"),"analysis_id 누락","OK")),IF(F28="","","OK"))))) -> OK | AQ28: 원문 scale=ratio. 1차 분석 = log 변환 ANOVA(p41)
A29: G-SB17-025 | B29: P_SB17 | C29: ST_SB17_1001 | D29: pk_gmr_cmax | E29: =IFERROR(INDEX(field_dictionary!$B:$B,MATCH($D29,field_dictionary!$A:$A,0)),"") -> PK | F29: =IFERROR(INDEX(field_dictionary!$C:$C,MATCH($D29,field_dictionary!$A:$A,0)),"") -> COMPARISON | G29: PRIMARY | H29: NA | I29: TEST_vs_US_RP | J29: PK_SET | K29: Single dose | L29: CORE | M29: NOT_FOUND | V29: SRC_EPAR_PYZ | AC29: p45 본문은 '90% CI가 기준 범위 안'이라고만 서술. 1차(ANOVA) 수치는 EPAR에 없음. 수치는 사후 ANCOVA(Table 7, p46)에만 있음 | AD29: N/A | AJ29: =IF(AE29="","",IF(AND(AE29=M29,ABS(N(AF29)-N(O29))<=0.01,ABS(N(AG29)-N(P29))<=0.01,ABS(N(AH29)-N(Q29))<=0.01),"Y","N")) | AM29: =IF(OR(AL29="",O29=""),"",IF(ABS(N(AL29)-N(O29))<=0.01,"Y","N")) | AN29: AI_DRAFT | AO29: =IFERROR(INDEX(studies!$L:$L,MATCH($C29,studies!$A:$A,0)),"") -> Y | AP29: =IF(AND(M29="REPORTED",V29=""),"출처 누락",IF(AND(M29="NOT_FOUND",AC29=""),"검색범위 누락",IF(F29="ARM",IF(OR(H29="",H29="NA"),"arm 누락","OK"),IF(F29="COMPARISON",IF(OR(I29="",I29="NA"),"비교쌍 누락",IF(OR(G29="",G29="NA"),"analysis_id 누락","OK")),IF(F29="","","OK"))))) -> OK | AQ29: 정성 결론은 pk_equiv_concluded 행에 기록
A30: G-SB17-026 | B30: P_SB17 | C30: ST_SB17_1001 | D30: pk_gmr_cmax | E30: =IFERROR(INDEX(field_dictionary!$B:$B,MATCH($D30,field_dictionary!$A:$A,0)),"") -> PK | F30: =IFERROR(INDEX(field_dictionary!$C:$C,MATCH($D30,field_dictionary!$A:$A,0)),"") -> COMPARISON | G30: PRIMARY | H30: NA | I30: EU_RP_vs_US_RP | J30: PK_SET | K30: Single dose | L30: CORE | M30: NOT_FOUND | V30: SRC_EPAR_PYZ | AC30: p45 본문은 '90% CI가 기준 범위 안'이라고만 서술. 1차(ANOVA) 수치는 EPAR에 없음. 수치는 사후 ANCOVA(Table 7, p46)에만 있음 | AD30: N/A | AJ30: =IF(AE30="","",IF(AND(AE30=M30,ABS(N(AF30)-N(O30))<=0.01,ABS(N(AG30)-N(P30))<=0.01,ABS(N(AH30)-N(Q30))<=0.01),"Y","N")) | AM30: =IF(OR(AL30="",O30=""),"",IF(ABS(N(AL30)-N(O30))<=0.01,"Y","N")) | AN30: AI_DRAFT | AO30: =IFERROR(INDEX(studies!$L:$L,MATCH($C30,studies!$A:$A,0)),"") -> Y | AP30: =IF(AND(M30="REPORTED",V30=""),"출처 누락",IF(AND(M30="NOT_FOUND",AC30=""),"검색범위 누락",IF(F30="ARM",IF(OR(H30="",H30="NA"),"arm 누락","OK"),IF(F30="COMPARISON",IF(OR(I30="",I30="NA"),"비교쌍 누락",IF(OR(G30="",G30="NA"),"analysis_id 누락","OK")),IF(F30="","","OK"))))) -> OK | AQ30: 정성 결론은 pk_equiv_concluded 행에 기록
A31: G-SB17-027 | B31: P_SB17 | C31: ST_SB17_1001 | D31: pk_gmr_auc_last | E31: =IFERROR(INDEX(field_dictionary!$B:$B,MATCH($D31,field_dictionary!$A:$A,0)),"") -> PK | F31: =IFERROR(INDEX(field_dictionary!$C:$C,MATCH($D31,field_dictionary!$A:$A,0)),"") -> COMPARISON | G31: PRIMARY | H31: NA | I31: TEST_vs_EU_RP | J31: PK_SET | K31: Single dose | L31: CORE | M31: NOT_FOUND | V31: SRC_EPAR_PYZ | AC31: AUClast는 p47 Table 8 기술통계(평균·SD)만 보고, 기하평균비 미보고 | AD31: N/A | AJ31: =IF(AE31="","",IF(AND(AE31=M31,ABS(N(AF31)-N(O31))<=0.01,ABS(N(AG31)-N(P31))<=0.01,ABS(N(AH31)-N(Q31))<=0.01),"Y","N")) | AM31: =IF(OR(AL31="",O31=""),"",IF(ABS(N(AL31)-N(O31))<=0.01,"Y","N")) | AN31: AI_DRAFT | AO31: =IFERROR(INDEX(studies!$L:$L,MATCH($C31,studies!$A:$A,0)),"") -> Y | AP31: =IF(AND(M31="REPORTED",V31=""),"출처 누락",IF(AND(M31="NOT_FOUND",AC31=""),"검색범위 누락",IF(F31="ARM",IF(OR(H31="",H31="NA"),"arm 누락","OK"),IF(F31="COMPARISON",IF(OR(I31="",I31="NA"),"비교쌍 누락",IF(OR(G31="",G31="NA"),"analysis_id 누락","OK")),IF(F31="","","OK"))))) -> OK
A32: G-SB17-028 | B32: P_SB17 | C32: ST_SB17_1001 | D32: pk_gmr_auc_last | E32: =IFERROR(INDEX(field_dictionary!$B:$B,MATCH($D32,field_dictionary!$A:$A,0)),"") -> PK | F32: =IFERROR(INDEX(field_dictionary!$C:$C,MATCH($D32,field_dictionary!$A:$A,0)),"") -> COMPARISON | G32: PRIMARY | H32: NA | I32: TEST_vs_US_RP | J32: PK_SET | K32: Single dose | L32: CORE | M32: NOT_FOUND | V32: SRC_EPAR_PYZ | AC32: AUClast는 p47 Table 8 기술통계(평균·SD)만 보고, 기하평균비 미보고 | AD32: N/A | AJ32: =IF(AE32="","",IF(AND(AE32=M32,ABS(N(AF32)-N(O32))<=0.01,ABS(N(AG32)-N(P32))<=0.01,ABS(N(AH32)-N(Q32))<=0.01),"Y","N")) | AM32: =IF(OR(AL32="",O32=""),"",IF(ABS(N(AL32)-N(O32))<=0.01,"Y","N")) | AN32: AI_DRAFT | AO32: =IFERROR(INDEX(studies!$L:$L,MATCH($C32,studies!$A:$A,0)),"") -> Y | AP32: =IF(AND(M32="REPORTED",V32=""),"출처 누락",IF(AND(M32="NOT_FOUND",AC32=""),"검색범위 누락",IF(F32="ARM",IF(OR(H32="",H32="NA"),"arm 누락","OK"),IF(F32="COMPARISON",IF(OR(I32="",I32="NA"),"비교쌍 누락",IF(OR(G32="",G32="NA"),"analysis_id 누락","OK")),IF(F32="","","OK"))))) -> OK
A33: G-SB17-029 | B33: P_SB17 | C33: ST_SB17_1001 | D33: pk_gmr_auc_last | E33: =IFERROR(INDEX(field_dictionary!$B:$B,MATCH($D33,field_dictionary!$A:$A,0)),"") -> PK | F33: =IFERROR(INDEX(field_dictionary!$C:$C,MATCH($D33,field_dictionary!$A:$A,0)),"") -> COMPARISON | G33: PRIMARY | H33: NA | I33: EU_RP_vs_US_RP | J33: PK_SET | K33: Single dose | L33: CORE | M33: NOT_FOUND | V33: SRC_EPAR_PYZ | AC33: AUClast는 p47 Table 8 기술통계(평균·SD)만 보고, 기하평균비 미보고 | AD33: N/A | AJ33: =IF(AE33="","",IF(AND(AE33=M33,ABS(N(AF33)-N(O33))<=0.01,ABS(N(AG33)-N(P33))<=0.01,ABS(N(AH33)-N(Q33))<=0.01),"Y","N")) | AM33: =IF(OR(AL33="",O33=""),"",IF(ABS(N(AL33)-N(O33))<=0.01,"Y","N")) | AN33: AI_DRAFT | AO33: =IFERROR(INDEX(studies!$L:$L,MATCH($C33,studies!$A:$A,0)),"") -> Y | AP33: =IF(AND(M33="REPORTED",V33=""),"출처 누락",IF(AND(M33="NOT_FOUND",AC33=""),"검색범위 누락",IF(F33="ARM",IF(OR(H33="",H33="NA"),"arm 누락","OK"),IF(F33="COMPARISON",IF(OR(I33="",I33="NA"),"비교쌍 누락",IF(OR(G33="",G33="NA"),"analysis_id 누락","OK")),IF(F33="","","OK"))))) -> OK
A34: G-SB17-030 | B34: P_SB17 | C34: ST_SB17_1001 | D34: pk_equiv_concluded | E34: =IFERROR(INDEX(field_dictionary!$B:$B,MATCH($D34,field_dictionary!$A:$A,0)),"") -> PK | F34: =IFERROR(INDEX(field_dictionary!$C:$C,MATCH($D34,field_dictionary!$A:$A,0)),"") -> COMPARISON | G34: PRIMARY | H34: NA | I34: TEST_vs_EU_RP | J34: PK_SET | L34: CORE | M34: REPORTED | N34: Y | V34: SRC_EPAR_PYZ | W34: 45 | X34: Page 45/168 | Y34: Table 5 아래 본문 | Z34: TEXT | AA34: These values for the 90% CIs were within the predefined equivalence margin of 0.8 to 1.25 | AD34: PASS | AJ34: =IF(AE34="","",IF(AND(AE34=M34,ABS(N(AF34)-N(O34))<=0.01,ABS(N(AG34)-N(P34))<=0.01,ABS(N(AH34)-N(Q34))<=0.01),"Y","N")) | AM34: =IF(OR(AL34="",O34=""),"",IF(ABS(N(AL34)-N(O34))<=0.01,"Y","N")) | AN34: AI_DRAFT | AO34: =IFERROR(INDEX(studies!$L:$L,MATCH($C34,studies!$A:$A,0)),"") -> Y | AP34: =IF(AND(M34="REPORTED",V34=""),"출처 누락",IF(AND(M34="NOT_FOUND",AC34=""),"검색범위 누락",IF(F34="ARM",IF(OR(H34="",H34="NA"),"arm 누락","OK"),IF(F34="COMPARISON",IF(OR(I34="",I34="NA"),"비교쌍 누락",IF(OR(G34="",G34="NA"),"analysis_id 누락","OK")),IF(F34="","","OK"))))) -> OK | AQ34: Cmax CI가 1을 포함하지 않아 사후 ANCOVA 수행(p45)
A35: G-SB17-031 | B35: P_SB17 | C35: ST_SB17_1001 | D35: pk_equiv_concluded | E35: =IFERROR(INDEX(field_dictionary!$B:$B,MATCH($D35,field_dictionary!$A:$A,0)),"") -> PK | F35: =IFERROR(INDEX(field_dictionary!$C:$C,MATCH($D35,field_dictionary!$A:$A,0)),"") -> COMPARISON | G35: PRIMARY | H35: NA | I35: TEST_vs_US_RP | J35: PK_SET | L35: CORE | M35: REPORTED | N35: Y | V35: SRC_EPAR_PYZ | W35: 45 | X35: Page 45/168 | Y35: Table 5 아래 본문 | Z35: TEXT | AA35: Therefore, the PK profiles between Pyzchiva and US Stelara and between EU Stelara and US Stelara were equivalent. | AD35: PASS | AJ35: =IF(AE35="","",IF(AND(AE35=M35,ABS(N(AF35)-N(O35))<=0.01,ABS(N(AG35)-N(P35))<=0.01,ABS(N(AH35)-N(Q35))<=0.01),"Y","N")) | AM35: =IF(OR(AL35="",O35=""),"",IF(ABS(N(AL35)-N(O35))<=0.01,"Y","N")) | AN35: AI_DRAFT | AO35: =IFERROR(INDEX(studies!$L:$L,MATCH($C35,studies!$A:$A,0)),"") -> Y | AP35: =IF(AND(M35="REPORTED",V35=""),"출처 누락",IF(AND(M35="NOT_FOUND",AC35=""),"검색범위 누락",IF(F35="ARM",IF(OR(H35="",H35="NA"),"arm 누락","OK"),IF(F35="COMPARISON",IF(OR(I35="",I35="NA"),"비교쌍 누락",IF(OR(G35="",G35="NA"),"analysis_id 누락","OK")),IF(F35="","","OK"))))) -> OK
A36: G-SB17-032 | B36: P_SB17 | C36: ST_SB17_1001 | D36: pk_equiv_concluded | E36: =IFERROR(INDEX(field_dictionary!$B:$B,MATCH($D36,field_dictionary!$A:$A,0)),"") -> PK | F36: =IFERROR(INDEX(field_dictionary!$C:$C,MATCH($D36,field_dictionary!$A:$A,0)),"") -> COMPARISON | G36: PRIMARY | H36: NA | I36: EU_RP_vs_US_RP | J36: PK_SET | L36: CORE | M36: REPORTED | N36: Y | V36: SRC_EPAR_PYZ | W36: 45 | X36: Page 45/168 | Y36: Table 5 아래 본문 | Z36: TEXT | AA36: Therefore, the PK profiles between Pyzchiva and US Stelara and between EU Stelara and US Stelara were equivalent. | AD36: PASS | AJ36: =IF(AE36="","",IF(AND(AE36=M36,ABS(N(AF36)-N(O36))<=0.01,ABS(N(AG36)-N(P36))<=0.01,ABS(N(AH36)-N(Q36))<=0.01),"Y","N")) | AM36: =IF(OR(AL36="",O36=""),"",IF(ABS(N(AL36)-N(O36))<=0.01,"Y","N")) | AN36: AI_DRAFT | AO36: =IFERROR(INDEX(studies!$L:$L,MATCH($C36,studies!$A:$A,0)),"") -> Y | AP36: =IF(AND(M36="REPORTED",V36=""),"출처 누락",IF(AND(M36="NOT_FOUND",AC36=""),"검색범위 누락",IF(F36="ARM",IF(OR(H36="",H36="NA"),"arm 누락","OK"),IF(F36="COMPARISON",IF(OR(I36="",I36="NA"),"비교쌍 누락",IF(OR(G36="",G36="NA"),"analysis_id 누락","OK")),IF(F36="","","OK"))))) -> OK
A37: G-SB17-033 | B37: P_SB17 | C37: ST_SB17_1001 | D37: pk_gmr_auc_inf | E37: =IFERROR(INDEX(field_dictionary!$B:$B,MATCH($D37,field_dictionary!$A:$A,0)),"") -> PK | F37: =IFERROR(INDEX(field_dictionary!$C:$C,MATCH($D37,field_dictionary!$A:$A,0)),"") -> COMPARISON | G37: ADHOC_ANCOVA_WT | H37: NA | I37: TEST_vs_EU_RP | J37: PK_SET | K37: Single dose | L37: EXTRA | M37: REPORTED | N37: 1.01 (0.92, 1.11) | O37: 101 | P37: 92 | Q37: 111 | R37: % | S37: 62 | T37: 64 | V37: SRC_EPAR_PYZ | W37: 48 | X37: Page 48/168 | Y37: Table 8 아래 본문 | Z37: TEXT | AA37: The geometric LSMean ratios (90% CI) between Pyzchiva and EU Stelara for AUCinf and Cmax were 1.01 (0.92 to 1.11) and 0.93 (0.85 to 1.02) | AB37: p46 Table 7 (이미지) | AD37: PASS | AJ37: =IF(AE37="","",IF(AND(AE37=M37,ABS(N(AF37)-N(O37))<=0.01,ABS(N(AG37)-N(P37))<=0.01,ABS(N(AH37)-N(Q37))<=0.01),"Y","N")) | AM37: =IF(OR(AL37="",O37=""),"",IF(ABS(N(AL37)-N(O37))<=0.01,"Y","N")) | AN37: AI_DRAFT | AO37: =IFERROR(INDEX(studies!$L:$L,MATCH($C37,studies!$A:$A,0)),"") -> Y | AP37: =IF(AND(M37="REPORTED",V37=""),"출처 누락",IF(AND(M37="NOT_FOUND",AC37=""),"검색범위 누락",IF(F37="ARM",IF(OR(H37="",H37="NA"),"arm 누락","OK"),IF(F37="COMPARISON",IF(OR(I37="",I37="NA"),"비교쌍 누락",IF(OR(G37="",G37="NA"),"analysis_id 누락","OK")),IF(F37="","","OK"))))) -> OK | AQ37: 사후 분석. 1차 분석 값과 혼동 금지 (분석 함정 사례)
A38: G-SB17-034 | B38: P_SB17 | C38: ST_SB17_1001 | D38: pk_gmr_cmax | E38: =IFERROR(INDEX(field_dictionary!$B:$B,MATCH($D38,field_dictionary!$A:$A,0)),"") -> PK | F38: =IFERROR(INDEX(field_dictionary!$C:$C,MATCH($D38,field_dictionary!$A:$A,0)),"") -> COMPARISON | G38: ADHOC_ANCOVA_WT | H38: NA | I38: TEST_vs_EU_RP | J38: PK_SET | K38: Single dose | L38: EXTRA | M38: REPORTED | N38: 0.93 (0.85, 1.02) | O38: 93 | P38: 85 | Q38: 102 | R38: % | S38: 62 | T38: 64 | V38: SRC_EPAR_PYZ | W38: 48 | X38: Page 48/168 | Y38: Table 8 아래 본문 | Z38: TEXT | AA38: The geometric LSMean ratios (90% CI) between Pyzchiva and EU Stelara for AUCinf and Cmax were 1.01 (0.92 to 1.11) and 0.93 (0.85 to 1.02) | AB38: p46 Table 7 (이미지) | AD38: PASS | AJ38: =IF(AE38="","",IF(AND(AE38=M38,ABS(N(AF38)-N(O38))<=0.01,ABS(N(AG38)-N(P38))<=0.01,ABS(N(AH38)-N(Q38))<=0.01),"Y","N")) | AM38: =IF(OR(AL38="",O38=""),"",IF(ABS(N(AL38)-N(O38))<=0.01,"Y","N")) | AN38: AI_DRAFT | AO38: =IFERROR(INDEX(studies!$L:$L,MATCH($C38,studies!$A:$A,0)),"") -> Y | AP38: =IF(AND(M38="REPORTED",V38=""),"출처 누락",IF(AND(M38="NOT_FOUND",AC38=""),"검색범위 누락",IF(F38="ARM",IF(OR(H38="",H38="NA"),"arm 누락","OK"),IF(F38="COMPARISON",IF(OR(I38="",I38="NA"),"비교쌍 누락",IF(OR(G38="",G38="NA"),"analysis_id 누락","OK")),IF(F38="","","OK"))))) -> OK | AQ38: 사후 분석. 1차 분석 값과 혼동 금지 (분석 함정 사례)
A39: G-SB17-035 | B39: P_SB17 | C39: ST_SB17_1001 | D39: pk_gmr_auc_inf | E39: =IFERROR(INDEX(field_dictionary!$B:$B,MATCH($D39,field_dictionary!$A:$A,0)),"") -> PK | F39: =IFERROR(INDEX(field_dictionary!$C:$C,MATCH($D39,field_dictionary!$A:$A,0)),"") -> COMPARISON | G39: ADHOC_ANCOVA_WT | H39: NA | I39: TEST_vs_US_RP | J39: PK_SET | K39: Single dose | L39: EXTRA | M39: REPORTED | N39: 1.02 (0.94, 1.12) | O39: 102 | P39: 94 | Q39: 112 | R39: % | S39: 62 | T39: 60 | V39: SRC_EPAR_PYZ | W39: 46 | X39: Page 46/168 | Y39: Table 7 (ad-hoc ANCOVA, 체중 공변량) | Z39: IMAGE | AD39: IMAGE(시각 확인) | AJ39: =IF(AE39="","",IF(AND(AE39=M39,ABS(N(AF39)-N(O39))<=0.01,ABS(N(AG39)-N(P39))<=0.01,ABS(N(AH39)-N(Q39))<=0.01),"Y","N")) | AM39: =IF(OR(AL39="",O39=""),"",IF(ABS(N(AL39)-N(O39))<=0.01,"Y","N")) | AN39: AI_DRAFT | AO39: =IFERROR(INDEX(studies!$L:$L,MATCH($C39,studies!$A:$A,0)),"") -> Y | AP39: =IF(AND(M39="REPORTED",V39=""),"출처 누락",IF(AND(M39="NOT_FOUND",AC39=""),"검색범위 누락",IF(F39="ARM",IF(OR(H39="",H39="NA"),"arm 누락","OK"),IF(F39="COMPARISON",IF(OR(I39="",I39="NA"),"비교쌍 누락",IF(OR(G39="",G39="NA"),"analysis_id 누락","OK")),IF(F39="","","OK"))))) -> OK | AQ39: 사후 분석. 1차 분석 값과 혼동 금지 (분석 함정 사례)
A40: G-SB17-036 | B40: P_SB17 | C40: ST_SB17_1001 | D40: pk_gmr_cmax | E40: =IFERROR(INDEX(field_dictionary!$B:$B,MATCH($D40,field_dictionary!$A:$A,0)),"") -> PK | F40: =IFERROR(INDEX(field_dictionary!$C:$C,MATCH($D40,field_dictionary!$A:$A,0)),"") -> COMPARISON | G40: ADHOC_ANCOVA_WT | H40: NA | I40: TEST_vs_US_RP | J40: PK_SET | K40: Single dose | L40: EXTRA | M40: REPORTED | N40: 0.96 (0.88, 1.05) | O40: 96 | P40: 88 | Q40: 105 | R40: % | S40: 62 | T40: 60 | V40: SRC_EPAR_PYZ | W40: 46 | X40: Page 46/168 | Y40: Table 7 (ad-hoc ANCOVA, 체중 공변량) | Z40: IMAGE | AD40: IMAGE(시각 확인) | AJ40: =IF(AE40="","",IF(AND(AE40=M40,ABS(N(AF40)-N(O40))<=0.01,ABS(N(AG40)-N(P40))<=0.01,ABS(N(AH40)-N(Q40))<=0.01),"Y","N")) | AM40: =IF(OR(AL40="",O40=""),"",IF(ABS(N(AL40)-N(O40))<=0.01,"Y","N")) | AN40: AI_DRAFT | AO40: =IFERROR(INDEX(studies!$L:$L,MATCH($C40,studies!$A:$A,0)),"") -> Y | AP40: =IF(AND(M40="REPORTED",V40=""),"출처 누락",IF(AND(M40="NOT_FOUND",AC40=""),"검색범위 누락",IF(F40="ARM",IF(OR(H40="",H40="NA"),"arm 누락","OK"),IF(F40="COMPARISON",IF(OR(I40="",I40="NA"),"비교쌍 누락",IF(OR(G40="",G40="NA"),"analysis_id 누락","OK")),IF(F40="","","OK"))))) -> OK | AQ40: 사후 분석. 1차 분석 값과 혼동 금지 (분석 함정 사례)
...

Sheet studies
A1: study_key | B1: product_id | C1: sponsor_study_code | D1: registry_ids | E1: phase | F1: population | G1: design | H1: purpose | I1: role_in_dossier | J1: arms_randomized | K1: dose_route | L1: in_eval_set | M1: selection_reason | N1: epar_location | O1: verified | P1: notes
A2: ST_SB17_1001 | B2: P_SB17 | C2: SB17-1001 | D2: NCT04772274 | E2: 1 | F2: 건강인 남녀 18–55세 | G2: 무작위, 이중맹검, 3군 병행, 단회투여 | H2: PK_SIMILARITY | I2: PIVOTAL_PK | J2: SB17 67 / EU 67 / US 67 (총 201) | K2: 45 mg SC | L2: Y | M2: EMA 판정은 SB17 vs EU 비교 | N2: Pyzchiva EPAR p37–51, 49–50 | O2: Y | P2: 등록 ID는 수집 seed(CT.gov) 기준. EPAR에는 NCT 미기재
A3: ST_SB17_3001 | B3: P_SB17 | C3: SB17-3001 | D3: NCT04967508 | E3: 3 | F3: 중등도–중증 판상 건선 | G3: 무작위, 이중맹검, 다기관 | H3: EFFICACY_EQUIV | I3: PIVOTAL_EFFICACY | J3: PK 하위연구 142 (71/71) | K3: - | L3: N | M3: 효능 시험. 면역원성 확장 시 후보 | N3: p37, p52 | O3: Y
A4: ST_ABP_20190230 | B4: P_ABP654 | C4: 20190230 | D4: EPAR 미기재 | E4: 1 | F4: 건강인 18–45세, 체중 50–90 kg | G4: 무작위, 이중맹검, 단회투여, 3군 병행 | H4: PK_SIMILARITY | I4: PIVOTAL_PK | J4: 총 238 (군별 수 EPAR 미기재) | K4: 90 mg SC | L4: Y | M4: 유일한 PK 유사성 시험 | N4: Wezenla EPAR p41–48, 93–94 | O4: Y | P4: 등록 ID를 임의로 채우지 않음(웹 검색으로도 미확인)
A5: ST_ABP_20190232 | B5: P_ABP654 | C5: 20190232 | D5: NCT04607980 | E5: 3 | F5: 중등도–중증 판상 건선 | G5: 무작위, 다기관, 이중맹검, 활성대조. 28주 재무작위배정(스위칭) | H5: EFFICACY_EQUIV | I5: PIVOTAL_EFFICACY | J5: 563 | K5: 45/90 mg SC (체중별) | L5: N | M5: 효능 시험 | N5: p41, 45–46, 49 | O5: Y
A6: ST_ABP_20200417 | B6: P_ABP654 | C6: 20200417 | D6: NCT04761627; EudraCT 2020-005205-42 | E6: 3 | F6: 판상 건선 | G6: 상호교환성(스위칭) 시험 | H6: SWITCHING | I6: NOT_IN_EPAR | J6: 494 (등록부) | K6: - | L6: N | M6: 함정 사례: 'ABP 654 PK 결과'에 섞이기 쉬움 | N6: EPAR 언급 없음 | O6: Y | P6: v0.1에서 '20190232와 같은 시험일 수 있음'으로 둔 항목 → 별개 시험으로 확인(등록부 참여자 수 494 일치)
A7: ST_ABP_DEV | B7: P_ABP654 | C7: 확인 필요 | D7: 확인 필요 | E7: 1 | F7: 건강인 | G7: PFS vs 자동주사기 | H7: DEVICE_BRIDGING | I7: NOT_IN_EPAR | L7: N | M7: 기기 비교. 바이오시밀러성 근거 아님 | N7: EPAR 언급 없음 | O7: N | P7: PMC12875155
A8: ST_CTP43_1_1_P2 | B8: P_CTP43 | C8: CT-P43 1.1 (Part 2) | D8: NCT04428814 | E8: 1 | F8: 건강인 남성 | G8: 2파트; Part 2 = 무작위, 이중맹검, 3군 병행, 단회투여 | H8: PK_SIMILARITY | I8: PIVOTAL_PK | J8: CT-P43 80 / EU 82 / US 79 (총 241) | K8: 45 mg SC (PFS) | L8: Y | M8: AUC 동등성 미충족 시험 — 실패 사례로서 평가 가치 높음 | N8: Steqeyma EPAR p29–39, 110–111 | O8: Y | P8: Part 1(30명, CT-P43 14 / EU 16)은 안전성 파트로 평가 제외
A9: ST_CTP43_1_2 | B9: P_CTP43 | C9: CT-P43 1.2 | D9: EPAR 미기재 | E9: 1 | F9: 건강한 일본인 남성 | G9: 무작위, 이중맹검, 3군 병행, 단회투여 | H9: PK_SIMILARITY | I9: REPEAT_PK | J9: CT-P43 114 / EU 110 / US 107 (총 331) | K9: 45 mg SC (PFS) | L9: Y | M9: 1.1 Part 2 실패 후 단백질 함량을 맞춘 배치로 재수행 | N9: p29–30, 39–46, 111–112 | O9: Y | P9: 등록 ID 미확인(일본 등록부일 가능성)
A10: ST_CTP43_POOLED | B10: P_CTP43 | C10: 1.1 Part 2 + 1.2 통합 | D10: - | E10: - | F10: - | G10: 사후 통합 분석 | H10: OTHER | I10: POSTHOC_ANALYSIS | L10: Y | M10: EXTRA 행만 (점추정치 없는 부분 보고 사례) | N10: p51, 54–55 | O10: Y
A11: ST_CTP43_3_1 | B11: P_CTP43 | C11: CT-P43 3.1 | D11: NCT04673786 | E11: 3 | F11: 중등도–중증 판상 건선 | G11: 무작위, 이중맹검, 활성대조, 병행 | H11: EFFICACY_EQUIV | I11: PIVOTAL_EFFICACY | J11: CT-P43 256 / EU 253 (총 509) | K11: 45/90 mg SC (체중별) | L11: N | M11: 효능 시험 | N11: p30 | O11: Y
A12: ST_CTP43_DEV | B12: P_CTP43 | C12: 확인 필요 | D12: NCT06951828 | E12: 1 | F12: 건강인 남성 | G12: 자동주사기 vs PFS | H12: DEVICE_BRIDGING | I12: NOT_IN_EPAR | L12: N | M12: 기기 비교 | N12: EPAR 언급 없음 | O12: N

Sheet ambiguity_log
A1: id | B1: 발견 위치 | C1: v0.1 규칙으로 라벨링할 때 생긴 문제 | D1: v0.2 변경 | E1: 영향 필드
A2: A1 | B2: SB17 p43(1차 ANOVA) vs p46·48(사후 ANCOVA); CT-P43 p35 vs p37; p51 통합 분석 | C2: 같은 키(시험·필드·비교쌍)에 '정답'이 2~4개. 예: CT-P43 1.1 AUC 비율 124.36(1차) / 124.59(US 제외) / 114.32(보정) | D2: analysis_id 키 추가. 핵심 격자 = PRIMARY, 나머지는 EXTRA 행 | E2: pk_gmr_*
A3: A2 | B3: ABP p44 Table 5 'US vs EU' / SB17 p46 'EU/US' / CT-P43 'EU-Stelara/US-Stelara' | C3: 대조약끼리 비교의 방향(분자·분모)이 제품마다 다름. v0.1 enum은 EU_vs_US 하나뿐 | D3: comparison에 US_RP_vs_EU_RP 추가. 원문 방향 그대로 기록, 역수 변환 금지 | E3: comparison
